Workbook

Sheet warehouse stock
A1: Specification 1 | B1: Specification 2 | C1: Specification 3 | D1: Site | E1: Warehouse | F1: Physical date | G1: Financial date | H1: Reference | I1: Number | J1: Receipt | K1: Issue | L1: Quantity | N1: Financial Month
A2: 2 oz/SQM | B2: 85" | C2: AR | D2: BB | E2: 03-BB-WH03 | F2: 45657 | G2: 45657 | H2: Sales order | I2: SO25_000003 | K2: Sold | L2: -6360 | N2: {=TEXT(MyGrid[Financial date],"mmm")} -> Dec | Q2: opening warehouse stock 100000 unit
A3: 2 oz/SQM | B3: 85" | C3: AR | D3: BB | E3: 03-BB-WH03 | F3: 45657 | G3: 45657 | H3: Transaction | I3: IJ_030015 | J3: Purchased | L3: 1760 | N3: Dec | P3: Month | Q3: Warhouse | R3: Purchased | S3: Sold | T3: Present Stock
A4: 2 oz/SQM | B4: 85" | C4: AR | D4: BB | E4: 03-BB-WH03 | F4: 45657 | G4: 45657 | H4: Transaction | I4: IJ_030015 | J4: Purchased | L4: 800 | N4: Dec | P4: {=_xlfn.UNIQUE(_xlfn.HSTACK(TEXT(MyGrid[Financial date],"MMM"),MyGrid[Warehouse]))} -> Dec | Q4: 03-BB-WH03 | R4: {=SUMPRODUCT((TEXT(MyGrid[Financial date],"MMM")=$P4)*(MyGrid[Warehouse]=Q4)*(MyGrid[Receipt]="Purchased")*MyGrid[Quantity])} -> 2560 | S4: {=SUMPRODUCT((TEXT(MyGrid[Financial date],"MMM")=$P4)*(MyGrid[Warehouse]=$Q4)*(MyGrid[Issue]="Sold")*MyGrid[Quantity])} -> -6360 | T4: =100000+(R4+S4) -> 96200
A5: 2 oz/SQM | B5: 85" | C5: AR | D5: BB | E5: 03-BB-WH07 | F5: 45657 | G5: 45656 | H5: Sales order | I5: SO25_000001 | K5: Sold | L5: -12000 | N5: Dec | P5: Dec | Q5: 03-BB-WH07 | R5: {=SUMPRODUCT((TEXT(MyGrid[Financial date],"MMM")=$P5)*(MyGrid[Warehouse]=Q5)*(MyGrid[Receipt]="Purchased")*MyGrid[Quantity])} -> 0 | S5: {=SUMPRODUCT((TEXT(MyGrid[Financial date],"MMM")=$P5)*(MyGrid[Warehouse]=$Q5)*(MyGrid[Issue]="Sold")*MyGrid[Quantity])} -> -12000 | T5: =100000+(R5+S5) -> 88000
A6: 2 oz/SQM | B6: 85" | C6: AR | D6: BB | E6: 03-BB-WH07 | F6: 45658 | G6: 45658 | H6: Sales order | I6: SO25_000008 | K6: Sold | L6: -4000 | N6: Jan | P6: Jan | Q6: 03-BB-WH07 | R6: {=SUMPRODUCT((TEXT(MyGrid[Financial date],"MMM")=$P6)*(MyGrid[Warehouse]=Q6)*(MyGrid[Receipt]="Purchased")*MyGrid[Quantity])} -> 4000 | S6: {=SUMPRODUCT((TEXT(MyGrid[Financial date],"MMM")=$P6)*(MyGrid[Warehouse]=$Q6)*(MyGrid[Issue]="Sold")*MyGrid[Quantity])} -> -74880 | T6: =100000+(R6+S6) -> 29120
A7: 2 oz/SQM | B7: 85" | C7: AR | D7: BB | E7: 03-BB-WH07 | F7: 45658 | G7: 45658 | H7: Sales order | I7: SO25_000008 | K7: Sold | L7: -4000 | N7: Jan | P7: Jan | Q7: 03-BB-WH03 | R7: {=SUMPRODUCT((TEXT(MyGrid[Financial date],"MMM")=$P7)*(MyGrid[Warehouse]=Q7)*(MyGrid[Receipt]="Purchased")*MyGrid[Quantity])} -> 88640 | S7: {=SUMPRODUCT((TEXT(MyGrid[Financial date],"MMM")=$P7)*(MyGrid[Warehouse]=$Q7)*(MyGrid[Issue]="Sold")*MyGrid[Quantity])} -> -7439 | T7: =100000+(R7+S7) -> 181201
A8: 2 oz/SQM | B8: 85" | C8: AR | D8: BB | E8: 03-BB-WH03 | F8: 45658 | G8: 45658 | H8: Transaction | I8: IJ_030019 | J8: Purchased | L8: 7520 | N8: Jan | P8: Jan | Q8: 03-BB-WH02 | R8: {=SUMPRODUCT((TEXT(MyGrid[Financial date],"MMM")=$P8)*(MyGrid[Warehouse]=Q8)*(MyGrid[Receipt]="Purchased")*MyGrid[Quantity])} -> 0 | S8: {=SUMPRODUCT((TEXT(MyGrid[Financial date],"MMM")=$P8)*(MyGrid[Warehouse]=$Q8)*(MyGrid[Issue]="Sold")*MyGrid[Quantity])} -> -4000 | T8: =100000+(R8+S8) -> 96000
A9: 2 oz/SQM | B9: 85" | C9: AR | D9: BB | E9: 03-BB-WH02 | F9: 45659 | G9: 45659 | H9: Sales order | I9: SO25_000012 | K9: Sold | L9: -4000 | N9: Jan | P9: Jan | Q9: 03-BB-WH06 | R9: {=SUMPRODUCT((TEXT(MyGrid[Financial date],"MMM")=$P9)*(MyGrid[Warehouse]=Q9)*(MyGrid[Receipt]="Purchased")*MyGrid[Quantity])} -> 0 | S9: {=SUMPRODUCT((TEXT(MyGrid[Financial date],"MMM")=$P9)*(MyGrid[Warehouse]=$Q9)*(MyGrid[Issue]="Sold")*MyGrid[Quantity])} -> -4000 | T9: =100000+(R9+S9) -> 96000
A10: 2 oz/SQM | B10: 85" | C10: AR | D10: BB | E10: 03-BB-WH03 | F10: 45661 | G10: 45661 | H10: Transaction | I10: IJ_030026 | J10: Purchased | L10: 5040 | N10: Jan | P10: Feb | Q10: 03-BB-WH07 | R10: {=SUMPRODUCT((TEXT(MyGrid[Financial date],"MMM")=$P10)*(MyGrid[Warehouse]=Q10)*(MyGrid[Receipt]="Purchased")*MyGrid[Quantity])} -> 5080 | S10: {=SUMPRODUCT((TEXT(MyGrid[Financial date],"MMM")=$P10)*(MyGrid[Warehouse]=$Q10)*(MyGrid[Issue]="Sold")*MyGrid[Quantity])} -> -52990 | T10: =100000+(R10+S10) -> 52090
A11: 2 oz/SQM | B11: 85" | C11: AR | D11: BB | E11: 03-BB-WH03 | F11: 45661 | G11: 45661 | H11: Transaction | I11: IJ_030026 | J11: Purchased | L11: 2960 | N11: Jan | P11: Feb | Q11: 03-BB-WH03 | R11: {=SUMPRODUCT((TEXT(MyGrid[Financial date],"MMM")=$P11)*(MyGrid[Warehouse]=Q11)*(MyGrid[Receipt]="Purchased")*MyGrid[Quantity])} -> 43100 | S11: {=SUMPRODUCT((TEXT(MyGrid[Financial date],"MMM")=$P11)*(MyGrid[Warehouse]=$Q11)*(MyGrid[Issue]="Sold")*MyGrid[Quantity])} -> 0 | T11: =100000+(R11+S11) -> 143100
A12: 2 oz/SQM | B12: 85" | C12: AR | D12: BB | E12: 03-BB-WH07 | F12: 45661 | G12: 45661 | H12: Sales order | I12: SO25_000013 | K12: Sold | L12: -4000 | N12: Jan | P12: Mar | Q12: 03-BB-WH03 | R12: {=SUMPRODUCT((TEXT(MyGrid[Financial date],"MMM")=$P12)*(MyGrid[Warehouse]=Q12)*(MyGrid[Receipt]="Purchased")*MyGrid[Quantity])} -> 72700 | S12: {=SUMPRODUCT((TEXT(MyGrid[Financial date],"MMM")=$P12)*(MyGrid[Warehouse]=$Q12)*(MyGrid[Issue]="Sold")*MyGrid[Quantity])} -> -11840 | T12: =100000+(R12+S12) -> 160860
A13: 2 oz/SQM | B13: 85" | C13: AR | D13: BB | E13: 03-BB-WH03 | F13: 45664 | G13: 45664 | H13: Transaction | I13: IJ_030046 | J13: Purchased | L13: 4000 | N13: Jan | P13: Mar | Q13: 03-BB-WH07 | R13: {=SUMPRODUCT((TEXT(MyGrid[Financial date],"MMM")=$P13)*(MyGrid[Warehouse]=Q13)*(MyGrid[Receipt]="Purchased")*MyGrid[Quantity])} -> 0 | S13: {=SUMPRODUCT((TEXT(MyGrid[Financial date],"MMM")=$P13)*(MyGrid[Warehouse]=$Q13)*(MyGrid[Issue]="Sold")*MyGrid[Quantity])} -> -57040 | T13: =100000+(R13+S13) -> 42960
A14: 2 oz/SQM | B14: 85" | C14: AR | D14: BB | E14: 03-BB-WH03 | F14: 45665 | G14: 45665 | H14: Transaction | I14: IJ_030052 | J14: Purchased | L14: 4640 | N14: Jan | P14: Mar | Q14: 03-BB-WH06 | R14: {=SUMPRODUCT((TEXT(MyGrid[Financial date],"MMM")=$P14)*(MyGrid[Warehouse]=Q14)*(MyGrid[Receipt]="Purchased")*MyGrid[Quantity])} -> 2400 | S14: {=SUMPRODUCT((TEXT(MyGrid[Financial date],"MMM")=$P14)*(MyGrid[Warehouse]=$Q14)*(MyGrid[Issue]="Sold")*MyGrid[Quantity])} -> -2400 | T14: =100000+(R14+S14) -> 100000
A15: 2 oz/SQM | B15: 85" | C15: AR | D15: BB | E15: 03-BB-WH07 | F15: 45670 | G15: 45670 | H15: Sales order | I15: SO25_000031 | K15: Sold | L15: -3760 | N15: Jan | P15: Apr | Q15: 03-BB-WH03 | R15: {=SUMPRODUCT((TEXT(MyGrid[Financial date],"MMM")=$P15)*(MyGrid[Warehouse]=Q15)*(MyGrid[Receipt]="Purchased")*MyGrid[Quantity])} -> 28720 | S15: {=SUMPRODUCT((TEXT(MyGrid[Financial date],"MMM")=$P15)*(MyGrid[Warehouse]=$Q15)*(MyGrid[Issue]="Sold")*MyGrid[Quantity])} -> -8160 | T15: =100000+(R15+S15) -> 120560
A16: 2 oz/SQM | B16: 85" | C16: AR | D16: BB | E16: 03-BB-WH07 | F16: 45670 | G16: 45670 | H16: Sales order | I16: SO25_000031 | K16: Sold | L16: -4000 | N16: Jan | P16: Apr | Q16: 03-BB-WH08 | R16: {=SUMPRODUCT((TEXT(MyGrid[Financial date],"MMM")=$P16)*(MyGrid[Warehouse]=Q16)*(MyGrid[Receipt]="Purchased")*MyGrid[Quantity])} -> 0 | S16: {=SUMPRODUCT((TEXT(MyGrid[Financial date],"MMM")=$P16)*(MyGrid[Warehouse]=$Q16)*(MyGrid[Issue]="Sold")*MyGrid[Quantity])} -> -4000 | T16: =100000+(R16+S16) -> 96000
A17: 2 oz/SQM | B17: 85" | C17: AR | D17: BB | E17: 03-BB-WH07 | F17: 45672 | G17: 45672 | H17: Sales order | I17: SO25_000033 | K17: Sold | L17: -4000 | N17: Jan | P17: Apr | Q17: 03-BB-WH07 | R17: {=SUMPRODUCT((TEXT(MyGrid[Financial date],"MMM")=$P17)*(MyGrid[Warehouse]=Q17)*(MyGrid[Receipt]="Purchased")*MyGrid[Quantity])} -> 0 | S17: {=SUMPRODUCT((TEXT(MyGrid[Financial date],"MMM")=$P17)*(MyGrid[Warehouse]=$Q17)*(MyGrid[Issue]="Sold")*MyGrid[Quantity])} -> -25469 | T17: =100000+(R17+S17) -> 74531
A18: 2 oz/SQM | B18: 85" | C18: AR | D18: BB | E18: 03-BB-WH03 | F18: 45672 | G18: 45672 | H18: Transaction | I18: IJ_030084 | J18: Purchased | L18: 1600 | N18: Jan | P18: May | Q18: 03-BB-WH03 | R18: {=SUMPRODUCT((TEXT(MyGrid[Financial date],"MMM")=$P18)*(MyGrid[Warehouse]=Q18)*(MyGrid[Receipt]="Purchased")*MyGrid[Quantity])} -> 10800 | S18: {=SUMPRODUCT((TEXT(MyGrid[Financial date],"MMM")=$P18)*(MyGrid[Warehouse]=$Q18)*(MyGrid[Issue]="Sold")*MyGrid[Quantity])} -> 0 | T18: =100000+(R18+S18) -> 110800
A19: 2 oz/SQM | B19: 85" | C19: AR | D19: BB | E19: 03-BB-WH07 | F19: 45675 | G19: 45675 | H19: Sales order | I19: SO25_000035 | K19: Sold | L19: -4000 | N19: Jan | P19: May | Q19: 03-BB-WH07 | R19: {=SUMPRODUCT((TEXT(MyGrid[Financial date],"MMM")=$P19)*(MyGrid[Warehouse]=Q19)*(MyGrid[Receipt]="Purchased")*MyGrid[Quantity])} -> 0 | S19: {=SUMPRODUCT((TEXT(MyGrid[Financial date],"MMM")=$P19)*(MyGrid[Warehouse]=$Q19)*(MyGrid[Issue]="Sold")*MyGrid[Quantity])} -> -13831 | T19: =100000+(R19+S19) -> 86169
A20: 2 oz/SQM | B20: 85" | C20: AR | D20: BB | E20: 03-BB-WH03 | F20: 45676 | G20: 45676 | H20: Sales order | I20: SO25_000049 | K20: Sold | L20: -2140 | N20: Jan
A21: 2 oz/SQM | B21: 85" | C21: AR | D21: BB | E21: 03-BB-WH03 | F21: 45677 | G21: 45677 | H21: Transaction | I21: IJ_030106 | J21: Purchased | L21: 3600 | N21: Jan
A22: 2 oz/SQM | B22: 85" | C22: AR | D22: BB | E22: 03-BB-WH03 | F22: 45677 | G22: 45677 | H22: Transaction | I22: IJ_030106 | J22: Purchased | L22: 800 | N22: Jan
A23: 2 oz/SQM | B23: 85" | C23: AR | D23: BB | E23: 03-BB-WH03 | F23: 45678 | G23: 45678 | H23: Transaction | I23: IJ_030110 | J23: Purchased | L23: 880 | N23: Jan
A24: 2 oz/SQM | B24: 85" | C24: AR | D24: BB | E24: 03-BB-WH03 | F24: 45678 | G24: 45678 | H24: Transaction | I24: IJ_030110 | J24: Purchased | L24: 2800 | N24: Jan
A25: 2 oz/SQM | B25: 85" | C25: AR | D25: BB | E25: 03-BB-WH07 | F25: 45679 | G25: 45679 | H25: Sales order | I25: SO25_000046 | K25: Sold | L25: -2240 | N25: Jan
A26: 2 oz/SQM | B26: 85" | C26: AR | D26: BB | E26: 03-BB-WH03 | F26: 45679 | G26: 45679 | H26: Transaction | I26: IJ_030114 | J26: Purchased | L26: 1040 | N26: Jan
A27: 2 oz/SQM | B27: 85" | C27: AR | D27: BB | E27: 03-BB-WH07 | F27: 45680 | G27: 45680 | H27: Sales order | I27: SO25_000047 | K27: Sold | L27: -800 | N27: Jan
A28: 2 oz/SQM | B28: 85" | C28: AR | D28: BB | E28: 03-BB-WH03 | F28: 45680 | G28: 45680 | H28: Transaction | I28: IJ_030119 | J28: Purchased | L28: 6720 | N28: Jan
A29: 2 oz/SQM | B29: 85" | C29: AR | D29: BB | E29: 03-BB-WH03 | F29: 45682 | G29: 45682 | H29: Transaction | I29: IJ_030123 | J29: Purchased | L29: 1920 | N29: Jan
A30: 2 oz/SQM | B30: 85" | C30: AR | D30: BB | E30: 03-BB-WH07 | F30: 45682 | G30: 45682 | H30: Sales order | I30: SO25_000050 | K30: Sold | L30: -4000 | N30: Jan
A31: 2 oz/SQM | B31: 85" | C31: AR | D31: BB | E31: 03-BB-WH03 | F31: 45682 | G31: 45682 | H31: Transaction | I31: IJ_030123 | J31: Purchased | L31: 3280 | N31: Jan
A32: 2 oz/SQM | B32: 85" | C32: AR | D32: BB | E32: 03-BB-WH07 | F32: 45683 | G32: 45683 | H32: Sales order | I32: SO25_000053 | K32: Sold | L32: -4800 | N32: Jan
A33: 2 oz/SQM | B33: 85" | C33: AR | D33: BB | E33: 03-BB-WH07 | F33: 45683 | G33: 45683 | H33: Sales order | I33: SO25_000053 | K33: Sold | L33: -4000 | N33: Jan
A34: 2 oz/SQM | B34: 85" | C34: AR | D34: BB | E34: 03-BB-WH03 | F34: 45683 | G34: 45683 | H34: Transaction | I34: IJ_030124 | J34: Purchased | L34: 3200 | N34: Jan
A35: 2 oz/SQM | B35: 85" | C35: AR | D35: BB | E35: 03-BB-WH03 | F35: 45683 | G35: 45683 | H35: Transaction | I35: IJ_030124 | J35: Purchased | L35: 4560 | N35: Jan
A36: 2 oz/SQM | B36: 85" | C36: AR | D36: BB | E36: 03-BB-WH03 | F36: 45684 | G36: 45684 | H36: Transaction | I36: IJ_030129 | J36: Purchased | L36: 3360 | N36: Jan
A37: 2 oz/SQM | B37: 85" | C37: AR | D37: BB | E37: 03-BB-WH07 | F37: 45685 | G37: 45685 | H37: Sales order | I37: SO25_000060 | J37: Purchased | L37: 4000 | N37: Jan
A38: 2 oz/SQM | B38: 85" | C38: AR | D38: BB | E38: 03-BB-WH07 | F38: 45685 | G38: 45685 | H38: Sales order | I38: SO25_000060 | K38: Sold | L38: -4000 | N38: Jan
A39: 2 oz/SQM | B39: 85" | C39: AR | D39: BB | E39: 03-BB-WH03 | F39: 45685 | G39: 45685 | H39: Transaction | I39: IJ_030133 | J39: Purchased | L39: 4000 | N39: Jan
A40: 2 oz/SQM | B40: 85" | C40: AR | D40: BB | E40: 03-BB-WH07 | F40: 45686 | G40: 45686 | H40: Sales order | I40: SO25_000062 | K40: Sold | L40: -5040 | N40: Jan
...

Sheet Stock by Warehouse
E2: Current Stock Level per Warehouse
D4: Warehouse | E4: Initial Stock | F4: Total Purchases | G4: Total Sales | H4: Current Stock
D5: {=_xlfn.UNIQUE(MyGrid[Warehouse])} -> 03-BB-WH03 | E5: 100000 | F5: =SUMIFS(MyGrid[Quantity],MyGrid[Warehouse],D5,MyGrid[Receipt],"Purchased") -> 246520 | G5: =SUMIFS(MyGrid[Quantity],MyGrid[Warehouse],$D5,MyGrid[Issue],"Sold") -> -33799 | H5: =E5+(F5+(G5)) -> 312721
D6: 03-BB-WH07 | E6: 100000 | F6: =SUMIFS(MyGrid[Quantity],MyGrid[Warehouse],D6,MyGrid[Receipt],"Purchased") -> 9080 | G6: =SUMIFS(MyGrid[Quantity],MyGrid[Warehouse],$D6,MyGrid[Issue],"Sold") -> -236210 | H6: =E6+(F6+(G6)) -> -127130
D7: 03-BB-WH02 | E7: 100000 | F7: =SUMIFS(MyGrid[Quantity],MyGrid[Warehouse],D7,MyGrid[Receipt],"Purchased") -> 0 | G7: =SUMIFS(MyGrid[Quantity],MyGrid[Warehouse],$D7,MyGrid[Issue],"Sold") -> -4000 | H7: =E7+(F7+(G7)) -> 96000
D8: 03-BB-WH06 | E8: 100000 | F8: =SUMIFS(MyGrid[Quantity],MyGrid[Warehouse],D8,MyGrid[Receipt],"Purchased") -> 2400 | G8: =SUMIFS(MyGrid[Quantity],MyGrid[Warehouse],$D8,MyGrid[Issue],"Sold") -> -6400 | H8: =E8+(F8+(G8)) -> 96000
D9: 03-BB-WH08 | E9: 100000 | F9: =SUMIFS(MyGrid[Quantity],MyGrid[Warehouse],D9,MyGrid[Receipt],"Purchased") -> 0 | G9: =SUMIFS(MyGrid[Quantity],MyGrid[Warehouse],$D9,MyGrid[Issue],"Sold") -> -4000 | H9: =E9+(F9+(G9)) -> 96000
E13: Monthly Warehouse Stock
D15: Month | E15: Jan
D17: Warehouse | E17: Purchases | F17: Sales | G17: Transactions | H17: Stock at Month End
D18: {=_xlfn.UNIQUE(MyGrid[Warehouse])} -> 03-BB-WH03 | E18: {=SUMPRODUCT((TEXT(MyGrid[Financial date],"MMM")=$E$15)*(MyGrid[Warehouse]=D18)*(MyGrid[Receipt]="Purchased")*MyGrid[Quantity])} -> 88640 | F18: {=SUMPRODUCT((TEXT(MyGrid[Financial date],"MMM")=$E$15)*(MyGrid[Warehouse]=D18)*(MyGrid[Issue]="Sold")*MyGrid[Quantity])} -> -7439 | G18: =COUNTIFS(MyGrid[Warehouse],D18,_xlfn.ANCHORARRAY('warehouse stock'!$N$2),'Stock by Warehouse'!$E$15) -> 26 | H18: {=100000+SUMPRODUCT((TEXT(MyGrid[Financial date],"MMM")=$E$15)*(MyGrid[Warehouse]=D18)*(MyGrid[Receipt]="Purchased")*MyGrid[Quantity])+SUMPRODUCT((TEXT(MyGrid[Financial date],"MMM")=D18)*(MyGrid[Warehouse]=D18)*(MyGrid[Issue]="Sold")*MyGrid[Quantity])} -> 188640
D19: 03-BB-WH07 | E19: {=SUMPRODUCT((TEXT(MyGrid[Financial date],"MMM")=$E$15)*(MyGrid[Warehouse]=D19)*(MyGrid[Receipt]="Purchased")*MyGrid[Quantity])} -> 4000 | F19: {=SUMPRODUCT((TEXT(MyGrid[Financial date],"MMM")=$E$15)*(MyGrid[Warehouse]=D19)*(MyGrid[Issue]="Sold")*MyGrid[Quantity])} -> -74880 | G19: =COUNTIFS(MyGrid[Warehouse],D19,_xlfn.ANCHORARRAY('warehouse stock'!$N$2),'Stock by Warehouse'!$E$15) -> 21 | H19: {=100000+SUMPRODUCT((TEXT(MyGrid[Financial date],"MMM")=$E$15)*(MyGrid[Warehouse]=D19)*(MyGrid[Receipt]="Purchased")*MyGrid[Quantity])+SUMPRODUCT((TEXT(MyGrid[Financial date],"MMM")=D19)*(MyGrid[Warehouse]=D19)*(MyGrid[Issue]="Sold")*MyGrid[Quantity])} -> 104000
D20: 03-BB-WH02 | E20: {=SUMPRODUCT((TEXT(MyGrid[Financial date],"MMM")=$E$15)*(MyGrid[Warehouse]=D20)*(MyGrid[Receipt]="Purchased")*MyGrid[Quantity])} -> 0 | F20: {=SUMPRODUCT((TEXT(MyGrid[Financial date],"MMM")=$E$15)*(MyGrid[Warehouse]=D20)*(MyGrid[Issue]="Sold")*MyGrid[Quantity])} -> -4000 | G20: =COUNTIFS(MyGrid[Warehouse],D20,_xlfn.ANCHORARRAY('warehouse stock'!$N$2),'Stock by Warehouse'!$E$15) -> 1 | H20: {=100000+SUMPRODUCT((TEXT(MyGrid[Financial date],"MMM")=$E$15)*(MyGrid[Warehouse]=D20)*(MyGrid[Receipt]="Purchased")*MyGrid[Quantity])+SUMPRODUCT((TEXT(MyGrid[Financial date],"MMM")=D20)*(MyGrid[Warehouse]=D20)*(MyGrid[Issue]="Sold")*MyGrid[Quantity])} -> 100000
D21: 03-BB-WH06 | E21: {=SUMPRODUCT((TEXT(MyGrid[Financial date],"MMM")=$E$15)*(MyGrid[Warehouse]=D21)*(MyGrid[Receipt]="Purchased")*MyGrid[Quantity])} -> 0 | F21: {=SUMPRODUCT((TEXT(MyGrid[Financial date],"MMM")=$E$15)*(MyGrid[Warehouse]=D21)*(MyGrid[Issue]="Sold")*MyGrid[Quantity])} -> -4000 | G21: =COUNTIFS(MyGrid[Warehouse],D21,_xlfn.ANCHORARRAY('warehouse stock'!$N$2),'Stock by Warehouse'!$E$15) -> 1 | H21: {=100000+SUMPRODUCT((TEXT(MyGrid[Financial date],"MMM")=$E$15)*(MyGrid[Warehouse]=D21)*(MyGrid[Receipt]="Purchased")*MyGrid[Quantity])+SUMPRODUCT((TEXT(MyGrid[Financial date],"MMM")=D21)*(MyGrid[Warehouse]=D21)*(MyGrid[Issue]="Sold")*MyGrid[Quantity])} -> 100000
D22: 03-BB-WH08 | E22: {=SUMPRODUCT((TEXT(MyGrid[Financial date],"MMM")=$E$15)*(MyGrid[Warehouse]=D22)*(MyGrid[Receipt]="Purchased")*MyGrid[Quantity])} -> 0 | F22: {=SUMPRODUCT((TEXT(MyGrid[Financial date],"MMM")=$E$15)*(MyGrid[Warehouse]=D22)*(MyGrid[Issue]="Sold")*MyGrid[Quantity])} -> 0 | G22: =COUNTIFS(MyGrid[Warehouse],D22,_xlfn.ANCHORARRAY('warehouse stock'!$N$2),'Stock by Warehouse'!$E$15) -> 0 | H22: {=100000+SUMPRODUCT((TEXT(MyGrid[Financial date],"MMM")=$E$15)*(MyGrid[Warehouse]=D22)*(MyGrid[Receipt]="Purchased")*MyGrid[Quantity])+SUMPRODUCT((TEXT(MyGrid[Financial date],"MMM")=D22)*(MyGrid[Warehouse]=D22)*(MyGrid[Issue]="Sold")*MyGrid[Quantity])} -> 100000
