Workbook

Sheet Row data
A1: SL | B1: CompName | C1: EmpId | D1: Employee Name | E1: DeptName | F1: SectName | G1: DesigName | H1: AccountNo | I1: JDate | J1: QuitDate | K1: Quit_Year | L1: BirthDate | M1: Age | N1: Gender | O1: OT | P1: Employee Category | Q1: Gross | R1: Gross Pay | S1: Basic | T1: HRent | U1: Medical | V1: TechAllowance | W1: ExtraTechAllow | X1: OthersAllowance | Y1: FoodAllowance | Z1: ConvAllowance | AA1: Attendance Bonus | AB1: OT Amount | AC1: Adjustment Deduction | AD1: Adjustment Addition | AE1: Absent Amount | AF1: Late Amount | AG1: Loan | AH1: Tax | AI1: Stamp | AJ1: Net Payable | AK1: Bank | AL1: Cash
A2: 1 | B2: ABC Company Ltd. | C2: 8143412 | D2: Abdullah | E2: Production | F2: Allora | G2: Trainee Officer | H2: 9993204000003460 | I2: 45078 | L2: 37622 | M2: =IF('Row data'!$J2="",DATEDIF('Row data'!$L2,TODAY(),"y"),"0") -> 23 | N2: M | O2: N | P2: Staff | Q2: 16305 | R2: 16305 | S2: 9783 | T2: 4892 | U2: 652 | V2: 489 | W2: 0 | X2: 0 | Y2: 489 | Z2: 489 | AA2: 0 | AB2: 0 | AC2: 0 | AD2: 0 | AE2: 0 | AF2: 0 | AG2: 0 | AH2: 0 | AI2: 0 | AJ2: ='Row data'!$S2+'Row data'!$T2+'Row data'!$U2+'Row data'!$W2+'Row data'!$X2+'Row data'!$Y2+'Row data'!$Z2+'Row data'!$AA2+'Row data'!$AB2+'Row data'!$AD2-'Row data'!$AC2-'Row data'!$AE2-'Row data'!$AF2-'Row data'!$AG2-'Row data'!$AH2-'Row data'!$AI2 -> 16305 | AK2: 16305 | AL2: 0
A3: 2 | B3: ABC Company Ltd. | C3: 7835403 | D3: Abir | E3: Production | F3: Fabric Tearing | G3: Head Fitter | H3: 9993201000357870 | I3: 44485 | J3: 44867 | K3: =YEAR('Row data'!$J3) -> 2022 | L3: 28431 | M3: =IF('Row data'!$J3="",DATEDIF('Row data'!$L3,TODAY(),"y"),"0") -> 0 | N3: M | O3: N | P3: Staff | Q3: 32700 | R3: 32700 | S3: 19620 | T3: 9810 | U3: 1308 | V3: 981 | W3: 0 | X3: 0 | Y3: 981 | Z3: 981 | AA3: 0 | AB3: 0 | AC3: 0 | AD3: 0 | AE3: 0 | AF3: 0 | AG3: 0 | AH3: 0 | AI3: 0 | AJ3: ='Row data'!$S3+'Row data'!$T3+'Row data'!$U3+'Row data'!$W3+'Row data'!$X3+'Row data'!$Y3+'Row data'!$Z3+'Row data'!$AA3+'Row data'!$AB3+'Row data'!$AD3-'Row data'!$AC3-'Row data'!$AE3-'Row data'!$AF3-'Row data'!$AG3-'Row data'!$AH3-'Row data'!$AI3 -> 32700 | AK3: 32700 | AL3: 0
A4: 3 | B4: ABC Company Ltd. | C4: 8538860 | D4: Ahsan | E4: Production | F4: Fabric Tearing | G4: Assistant | H4: 703204000030529 | I4: 43996 | J4: 44562 | K4: =YEAR('Row data'!$J4) -> 2022 | L4: 32874 | M4: =IF('Row data'!$J4="",DATEDIF('Row data'!$L4,TODAY(),"y"),"0") -> 0 | N4: M | O4: N | P4: Staff | Q4: 16351 | R4: 16024 | S4: 9810 | T4: 4905 | U4: 654 | V4: 491 | W4: 0 | X4: 0 | Y4: 491 | Z4: 491 | AA4: 0 | AB4: 0 | AC4: -327 | AD4: 0 | AE4: 0 | AF4: 0 | AG4: 0 | AH4: 0 | AI4: 0 | AJ4: ='Row data'!$S4+'Row data'!$T4+'Row data'!$U4+'Row data'!$W4+'Row data'!$X4+'Row data'!$Y4+'Row data'!$Z4+'Row data'!$AA4+'Row data'!$AB4+'Row data'!$AD4-'Row data'!$AC4-'Row data'!$AE4-'Row data'!$AF4-'Row data'!$AG4-'Row data'!$AH4-'Row data'!$AI4 -> 16678 | AK4: 16024 | AL4: 0
A5: 4 | B5: ABC Company Ltd. | C5: 8627585 | D5: Akash | E5: Production | F5: Fabric Tearing | G5: Senior Fitter | H5: 9993204000003280 | I5: 44531 | L5: 33238 | M5: =IF('Row data'!$J5="",DATEDIF('Row data'!$L5,TODAY(),"y"),"0") -> 35 | N5: M | O5: N | P5: Staff | Q5: 24526 | R5: 24526 | S5: 14715 | T5: 7358 | U5: 981 | V5: 736 | W5: 0 | X5: 0 | Y5: 736 | Z5: 736 | AA5: 0 | AB5: 0 | AC5: 0 | AD5: 0 | AE5: 0 | AF5: 0 | AG5: 0 | AH5: 0 | AI5: 0 | AJ5: ='Row data'!$S5+'Row data'!$T5+'Row data'!$U5+'Row data'!$W5+'Row data'!$X5+'Row data'!$Y5+'Row data'!$Z5+'Row data'!$AA5+'Row data'!$AB5+'Row data'!$AD5-'Row data'!$AC5-'Row data'!$AE5-'Row data'!$AF5-'Row data'!$AG5-'Row data'!$AH5-'Row data'!$AI5 -> 24526 | AK5: 24526 | AL5: 0
A6: 5 | B6: ABC Company Ltd. | C6: 9077918 | D6: Alamgir | E6: Production | F6: Heatbond | G6: Shift Engineer | H6: 9993204000003430 | I6: 44516 | L6: 34699 | M6: =IF('Row data'!$J6="",DATEDIF('Row data'!$L6,TODAY(),"y"),"0") -> 31 | N6: M | O6: N | P6: Staff | Q6: 27251 | R6: 27251 | S6: 16350 | T6: 8175 | U6: 1090 | V6: 818 | W6: 0 | X6: 0 | Y6: 818 | Z6: 818 | AA6: 0 | AB6: 0 | AC6: 0 | AD6: 0 | AE6: 0 | AF6: 0 | AG6: 0 | AH6: 0 | AI6: 0 | AJ6: ='Row data'!$S6+'Row data'!$T6+'Row data'!$U6+'Row data'!$W6+'Row data'!$X6+'Row data'!$Y6+'Row data'!$Z6+'Row data'!$AA6+'Row data'!$AB6+'Row data'!$AD6-'Row data'!$AC6-'Row data'!$AE6-'Row data'!$AF6-'Row data'!$AG6-'Row data'!$AH6-'Row data'!$AI6 -> 27251 | AK6: 27251 | AL6: 0
A7: 6 | B7: ABC Company Ltd. | C7: 6259828 | D7: Alif | E7: Production | F7: Heatbond | G7: Shift Engineer | H7: 9993204000003420 | I7: 44516 | L7: 35632 | M7: =IF('Row data'!$J7="",DATEDIF('Row data'!$L7,TODAY(),"y"),"0") -> 29 | N7: M | O7: N | P7: Staff | Q7: 26160 | R7: 26160 | S7: 15696 | T7: 7848 | U7: 1046 | V7: 785 | W7: 0 | X7: 0 | Y7: 785 | Z7: 785 | AA7: 0 | AB7: 0 | AC7: 0 | AD7: 0 | AE7: 0 | AF7: 0 | AG7: 0 | AH7: 0 | AI7: 0 | AJ7: ='Row data'!$S7+'Row data'!$T7+'Row data'!$U7+'Row data'!$W7+'Row data'!$X7+'Row data'!$Y7+'Row data'!$Z7+'Row data'!$AA7+'Row data'!$AB7+'Row data'!$AD7-'Row data'!$AC7-'Row data'!$AE7-'Row data'!$AF7-'Row data'!$AG7-'Row data'!$AH7-'Row data'!$AI7 -> 26160 | AK7: 26160 | AL7: 0
A8: 7 | B8: ABC Company Ltd. | C8: 9833929 | D8: Aminul | E8: Production | F8: Heatbond | G8: Senior Supervisor | H8: 703204000030573 | I8: 36968 | J8: 44562 | K8: =YEAR('Row data'!$J8) -> 2022 | L8: 30713 | M8: =IF('Row data'!$J8="",DATEDIF('Row data'!$L8,TODAY(),"y"),"0") -> 0 | N8: M | O8: N | P8: Staff | Q8: 32700 | R8: 32700 | S8: 19620 | T8: 9810 | U8: 1308 | V8: 981 | W8: 0 | X8: 0 | Y8: 981 | Z8: 981 | AA8: 0 | AB8: 0 | AC8: 0 | AD8: 0 | AE8: 0 | AF8: 0 | AG8: 15000 | AH8: 0 | AI8: 0 | AJ8: ='Row data'!$S8+'Row data'!$T8+'Row data'!$U8+'Row data'!$W8+'Row data'!$X8+'Row data'!$Y8+'Row data'!$Z8+'Row data'!$AA8+'Row data'!$AB8+'Row data'!$AD8-'Row data'!$AC8-'Row data'!$AE8-'Row data'!$AF8-'Row data'!$AG8-'Row data'!$AH8-'Row data'!$AI8 -> 17700 | AK8: 17700 | AL8: 0
A9: 8 | B9: ABC Company Ltd. | C9: 7400970 | D9: Anik | E9: Utility & Maintenance | F9: Electrical | G9: Junior Executive | H9: 9993204000003300 | I9: 44721 | L9: 36204 | M9: =IF('Row data'!$J9="",DATEDIF('Row data'!$L9,TODAY(),"y"),"0") -> 27 | N9: M | O9: N | P9: Staff | Q9: 16351 | R9: 16351 | S9: 9810 | T9: 4905 | U9: 654 | V9: 491 | W9: 0 | X9: 0 | Y9: 491 | Z9: 491 | AA9: 0 | AB9: 0 | AC9: 0 | AD9: 0 | AE9: 0 | AF9: 0 | AG9: 0 | AH9: 0 | AI9: 0 | AJ9: ='Row data'!$S9+'Row data'!$T9+'Row data'!$U9+'Row data'!$W9+'Row data'!$X9+'Row data'!$Y9+'Row data'!$Z9+'Row data'!$AA9+'Row data'!$AB9+'Row data'!$AD9-'Row data'!$AC9-'Row data'!$AE9-'Row data'!$AF9-'Row data'!$AG9-'Row data'!$AH9-'Row data'!$AI9 -> 16351 | AK9: 16351 | AL9: 0
A10: 9 | B10: ABC Textile Ltd. | C10: 5912367 | D10: Anisur | E10: Admin | F10: Canteen | G10: Assistant Cook | H10: 703204000030538 | I10: 44765 | L10: 25993 | M10: =IF('Row data'!$J10="",DATEDIF('Row data'!$L10,TODAY(),"y"),"0") -> 55 | N10: F | O10: N | P10: Staff | Q10: 16197 | R10: 16197 | S10: 9718 | T10: 4859 | U10: 648 | V10: 486 | W10: 0 | X10: 0 | Y10: 486 | Z10: 486 | AA10: 0 | AB10: 0 | AC10: 0 | AD10: 0 | AE10: 0 | AF10: 0 | AG10: 0 | AH10: 0 | AI10: 0 | AJ10: ='Row data'!$S10+'Row data'!$T10+'Row data'!$U10+'Row data'!$W10+'Row data'!$X10+'Row data'!$Y10+'Row data'!$Z10+'Row data'!$AA10+'Row data'!$AB10+'Row data'!$AD10-'Row data'!$AC10-'Row data'!$AE10-'Row data'!$AF10-'Row data'!$AG10-'Row data'!$AH10-'Row data'!$AI10 -> 16197 | AK10: 16197 | AL10: 0
A11: 10 | B11: ABC Textile Ltd. | C11: 9402867 | D11: Arif | E11: Admin | F11: Canteen | G11: Assistant Cook | H11: 703204000030981 | I11: 44784 | L11: 26689 | M11: =IF('Row data'!$J11="",DATEDIF('Row data'!$L11,TODAY(),"y"),"0") -> 53 | N11: F | O11: N | P11: Staff | Q11: 16197 | R11: 16197 | S11: 9718 | T11: 4859 | U11: 648 | V11: 486 | W11: 0 | X11: 0 | Y11: 486 | Z11: 486 | AA11: 0 | AB11: 0 | AC11: 0 | AD11: 0 | AE11: 0 | AF11: 0 | AG11: 0 | AH11: 0 | AI11: 0 | AJ11: ='Row data'!$S11+'Row data'!$T11+'Row data'!$U11+'Row data'!$W11+'Row data'!$X11+'Row data'!$Y11+'Row data'!$Z11+'Row data'!$AA11+'Row data'!$AB11+'Row data'!$AD11-'Row data'!$AC11-'Row data'!$AE11-'Row data'!$AF11-'Row data'!$AG11-'Row data'!$AH11-'Row data'!$AI11 -> 16197 | AK11: 16197 | AL11: 0
A12: 11 | B12: ABC Textile Ltd. | C12: 8167313 | D12: Ashfaq | E12: Admin | F12: Canteen | G12: Assistant | H12: 9993204000004140 | I12: 44501 | L12: 36178 | M12: =IF('Row data'!$J12="",DATEDIF('Row data'!$L12,TODAY(),"y"),"0") -> 27 | N12: M | O12: N | P12: Staff | Q12: 16260 | R12: 14260 | S12: 9756 | T12: 4878 | U12: 650 | V12: 488 | W12: 0 | X12: 0 | Y12: 488 | Z12: 488 | AA12: 0 | AB12: 0 | AC12: -2000 | AD12: 0 | AE12: 0 | AF12: 0 | AG12: 0 | AH12: 0 | AI12: 0 | AJ12: ='Row data'!$S12+'Row data'!$T12+'Row data'!$U12+'Row data'!$W12+'Row data'!$X12+'Row data'!$Y12+'Row data'!$Z12+'Row data'!$AA12+'Row data'!$AB12+'Row data'!$AD12-'Row data'!$AC12-'Row data'!$AE12-'Row data'!$AF12-'Row data'!$AG12-'Row data'!$AH12-'Row data'!$AI12 -> 18260 | AK12: 14260 | AL12: 0
A13: 12 | B13: ABC Textile Ltd. | C13: 7225567 | D13: Asif | E13: Admin | F13: Canteen | G13: Assistant Cook | H13: 9993204000004140 | I13: 45185 | L13: 28255 | M13: =IF('Row data'!$J13="",DATEDIF('Row data'!$L13,TODAY(),"y"),"0") -> 49 | N13: F | O13: N | P13: Staff | Q13: 15976 | R13: 15976 | S13: 9586 | T13: 4793 | U13: 639 | V13: 479 | W13: 0 | X13: 0 | Y13: 479 | Z13: 479 | AA13: 0 | AB13: 0 | AC13: 0 | AD13: 0 | AE13: 0 | AF13: 0 | AG13: 0 | AH13: 0 | AI13: 0 | AJ13: ='Row data'!$S13+'Row data'!$T13+'Row data'!$U13+'Row data'!$W13+'Row data'!$X13+'Row data'!$Y13+'Row data'!$Z13+'Row data'!$AA13+'Row data'!$AB13+'Row data'!$AD13-'Row data'!$AC13-'Row data'!$AE13-'Row data'!$AF13-'Row data'!$AG13-'Row data'!$AH13-'Row data'!$AI13 -> 15976 | AK13: 15976 | AL13: 0
A14: 13 | B14: ABC Textile Ltd. | C14: 8864098 | D14: Aziz | E14: Admin | F14: Canteen | G14: Cook | H14: 9993201000060010 | I14: 38261 | L14: 30746 | M14: =IF('Row data'!$J14="",DATEDIF('Row data'!$L14,TODAY(),"y"),"0") -> 42 | N14: M | O14: N | P14: Staff | Q14: 33791 | R14: 33791 | S14: 20274 | T14: 10137 | U14: 1352 | V14: 1014 | W14: 0 | X14: 0 | Y14: 1014 | Z14: 1014 | AA14: 0 | AB14: 0 | AC14: 0 | AD14: 0 | AE14: 0 | AF14: 0 | AG14: 0 | AH14: 0 | AI14: 0 | AJ14: ='Row data'!$S14+'Row data'!$T14+'Row data'!$U14+'Row data'!$W14+'Row data'!$X14+'Row data'!$Y14+'Row data'!$Z14+'Row data'!$AA14+'Row data'!$AB14+'Row data'!$AD14-'Row data'!$AC14-'Row data'!$AE14-'Row data'!$AF14-'Row data'!$AG14-'Row data'!$AH14-'Row data'!$AI14 -> 33791 | AK14: 33791 | AL14: 0
A15: 14 | B15: ABC Textile Ltd. | C15: 6516432 | D15: Badrul | E15: Admin | F15: Canteen | G15: Assistant Cook | I15: 44257 | L15: 32874 | M15: =IF('Row data'!$J15="",DATEDIF('Row data'!$L15,TODAY(),"y"),"0") -> 36 | N15: F | O15: N | P15: Staff | Q15: 15976 | R15: 15976 | S15: 9586 | T15: 4793 | U15: 639 | V15: 479 | W15: 0 | X15: 0 | Y15: 479 | Z15: 479 | AA15: 0 | AB15: 0 | AC15: 0 | AD15: 0 | AE15: 0 | AF15: 0 | AG15: 0 | AH15: 0 | AI15: 0 | AJ15: ='Row data'!$S15+'Row data'!$T15+'Row data'!$U15+'Row data'!$W15+'Row data'!$X15+'Row data'!$Y15+'Row data'!$Z15+'Row data'!$AA15+'Row data'!$AB15+'Row data'!$AD15-'Row data'!$AC15-'Row data'!$AE15-'Row data'!$AF15-'Row data'!$AG15-'Row data'!$AH15-'Row data'!$AI15 -> 15976 | AK15: 15976 | AL15: 0
A16: 15 | B16: ABC Textile Ltd. | C16: 7580318 | D16: Bashir | E16: Admin | F16: Factory Affairs | G16: Deputy General Manager | H16: 563201000085448 | I16: 44378 | J16: 44905 | K16: =YEAR('Row data'!$J16) -> 2022 | L16: 28469 | M16: =IF('Row data'!$J16="",DATEDIF('Row data'!$L16,TODAY(),"y"),"0") -> 0 | N16: M | O16: N | P16: Staff | Q16: 135000 | R16: 135000 | S16: 81000 | T16: 40500 | U16: 5400 | V16: 4050 | W16: 0 | X16: 0 | Y16: 4050 | Z16: 4050 | AA16: 0 | AB16: 0 | AC16: 0 | AD16: 0 | AE16: 0 | AF16: 0 | AG16: 0 | AH16: 3000 | AI16: 0 | AJ16: ='Row data'!$S16+'Row data'!$T16+'Row data'!$U16+'Row data'!$W16+'Row data'!$X16+'Row data'!$Y16+'Row data'!$Z16+'Row data'!$AA16+'Row data'!$AB16+'Row data'!$AD16-'Row data'!$AC16-'Row data'!$AE16-'Row data'!$AF16-'Row data'!$AG16-'Row data'!$AH16-'Row data'!$AI16 -> 132000 | AK16: 132000 | AL16: 0
A17: 16 | B17: ABC Textile Ltd. | C17: 7769663 | D17: Belal | E17: Admin | F17: Security | G17: Lady Checker | H17: 9993204000010980 | I17: 45701 | L17: 35796 | M17: =IF('Row data'!$J17="",DATEDIF('Row data'!$L17,TODAY(),"y"),"0") -> 28 | N17: F | O17: N | P17: Staff | Q17: 14300 | R17: 8171 | S17: 8580 | T17: 4290 | U17: 572 | V17: 429 | W17: 0 | X17: 0 | Y17: 429 | Z17: 429 | AA17: 0 | AB17: 0 | AC17: 0 | AD17: 0 | AE17: 6129 | AF17: 0 | AG17: 0 | AH17: 0 | AI17: 0 | AJ17: ='Row data'!$S17+'Row data'!$T17+'Row data'!$U17+'Row data'!$W17+'Row data'!$X17+'Row data'!$Y17+'Row data'!$Z17+'Row data'!$AA17+'Row data'!$AB17+'Row data'!$AD17-'Row data'!$AC17-'Row data'!$AE17-'Row data'!$AF17-'Row data'!$AG17-'Row data'!$AH17-'Row data'!$AI17 -> 8171 | AK17: 8171 | AL17: 0
A18: 17 | B18: ABC Textile Ltd. | C18: 8771000 | D18: Fahim | E18: Admin | F18: Supports | G18: Loader | H18: 9993204000010070 | I18: 44761 | L18: 34570 | M18: =IF('Row data'!$J18="",DATEDIF('Row data'!$L18,TODAY(),"y"),"0") -> 32 | N18: M | O18: N | P18: Staff | Q18: 15931 | R18: 15931 | S18: 9559 | T18: 4779 | U18: 637 | V18: 478 | W18: 0 | X18: 0 | Y18: 478 | Z18: 478 | AA18: 0 | AB18: 0 | AC18: 0 | AD18: 0 | AE18: 0 | AF18: 0 | AG18: 0 | AH18: 0 | AI18: 0 | AJ18: ='Row data'!$S18+'Row data'!$T18+'Row data'!$U18+'Row data'!$W18+'Row data'!$X18+'Row data'!$Y18+'Row data'!$Z18+'Row data'!$AA18+'Row data'!$AB18+'Row data'!$AD18-'Row data'!$AC18-'Row data'!$AE18-'Row data'!$AF18-'Row data'!$AG18-'Row data'!$AH18-'Row data'!$AI18 -> 15931 | AK18: 15931 | AL18: 0
A19: 18 | B19: ABC Textile Ltd. | C19: 8569356 | D19: Farhan | E19: Admin | F19: Supports | G19: Loader | H19: 9993204000009970 | I19: 44761 | L19: 26718 | M19: =IF('Row data'!$J19="",DATEDIF('Row data'!$L19,TODAY(),"y"),"0") -> 53 | N19: M | O19: N | P19: Staff | Q19: 15931 | R19: 15931 | S19: 9559 | T19: 4779 | U19: 637 | V19: 478 | W19: 0 | X19: 0 | Y19: 478 | Z19: 478 | AA19: 0 | AB19: 0 | AC19: 0 | AD19: 0 | AE19: 0 | AF19: 0 | AG19: 0 | AH19: 0 | AI19: 0 | AJ19: ='Row data'!$S19+'Row data'!$T19+'Row data'!$U19+'Row data'!$W19+'Row data'!$X19+'Row data'!$Y19+'Row data'!$Z19+'Row data'!$AA19+'Row data'!$AB19+'Row data'!$AD19-'Row data'!$AC19-'Row data'!$AE19-'Row data'!$AF19-'Row data'!$AG19-'Row data'!$AH19-'Row data'!$AI19 -> 15931 | AK19: 15931 | AL19: 0
A20: 19 | B20: ABC Textile Ltd. | C20: 9779338 | D20: Faruk | E20: Admin | F20: Supports | G20: Loader | H20: 9993204000010400 | I20: 45171 | L20: 31413 | M20: =IF('Row data'!$J20="",DATEDIF('Row data'!$L20,TODAY(),"y"),"0") -> 40 | N20: M | O20: N | P20: Staff | Q20: 15931 | R20: 15590 | S20: 9559 | T20: 4779 | U20: 637 | V20: 478 | W20: 0 | X20: 0 | Y20: 478 | Z20: 478 | AA20: 0 | AB20: 0 | AC20: 0 | AD20: 0 | AE20: 341 | AF20: 0 | AG20: 0 | AH20: 0 | AI20: 0 | AJ20: ='Row data'!$S20+'Row data'!$T20+'Row data'!$U20+'Row data'!$W20+'Row data'!$X20+'Row data'!$Y20+'Row data'!$Z20+'Row data'!$AA20+'Row data'!$AB20+'Row data'!$AD20-'Row data'!$AC20-'Row data'!$AE20-'Row data'!$AF20-'Row data'!$AG20-'Row data'!$AH20-'Row data'!$AI20 -> 15590 | AK20: 15590 | AL20: 0
A21: 20 | B21: ABC Textile Ltd. | C21: 5974872 | D21: Firoz | E21: Admin | F21: Supports | G21: Loader | H21: 9993204000010440 | I21: 44052 | L21: 30185 | M21: =IF('Row data'!$J21="",DATEDIF('Row data'!$L21,TODAY(),"y"),"0") -> 44 | N21: M | O21: N | P21: Staff | Q21: 16031 | R21: 16031 | S21: 9619 | T21: 4809 | U21: 641 | V21: 481 | W21: 0 | X21: 0 | Y21: 481 | Z21: 481 | AA21: 0 | AB21: 0 | AC21: 0 | AD21: 0 | AE21: 0 | AF21: 0 | AG21: 0 | AH21: 0 | AI21: 0 | AJ21: ='Row data'!$S21+'Row data'!$T21+'Row data'!$U21+'Row data'!$W21+'Row data'!$X21+'Row data'!$Y21+'Row data'!$Z21+'Row data'!$AA21+'Row data'!$AB21+'Row data'!$AD21-'Row data'!$AC21-'Row data'!$AE21-'Row data'!$AF21-'Row data'!$AG21-'Row data'!$AH21-'Row data'!$AI21 -> 16031 | AK21: 16031 | AL21: 0
A22: 21 | B22: ABC Textile Ltd. | C22: 5341375 | D22: Habib | E22: Admin | F22: Supports | G22: Loader | H22: 9993204000010490 | I22: 43282 | J22: 44854 | K22: =YEAR('Row data'!$J22) -> 2022 | L22: 28418 | M22: =IF('Row data'!$J22="",DATEDIF('Row data'!$L22,TODAY(),"y"),"0") -> 0 | N22: M | O22: N | P22: Staff | Q22: 16231 | R22: 16231 | S22: 9739 | T22: 4869 | U22: 649 | V22: 487 | W22: 0 | X22: 0 | Y22: 487 | Z22: 487 | AA22: 0 | AB22: 0 | AC22: 0 | AD22: 0 | AE22: 0 | AF22: 0 | AG22: 0 | AH22: 0 | AI22: 0 | AJ22: ='Row data'!$S22+'Row data'!$T22+'Row data'!$U22+'Row data'!$W22+'Row data'!$X22+'Row data'!$Y22+'Row data'!$Z22+'Row data'!$AA22+'Row data'!$AB22+'Row data'!$AD22-'Row data'!$AC22-'Row data'!$AE22-'Row data'!$AF22-'Row data'!$AG22-'Row data'!$AH22-'Row data'!$AI22 -> 16231 | AK22: 16231 | AL22: 0
A23: 22 | B23: ABC Textile Ltd. | C23: 8755179 | D23: Hafiz | E23: Admin | F23: Vehicle Management | G23: Driver | H23: 9993204000004970 | I23: 45598 | J23: 44562 | K23: =YEAR('Row data'!$J23) -> 2022 | L23: 32852 | M23: =IF('Row data'!$J23="",DATEDIF('Row data'!$L23,TODAY(),"y"),"0") -> 0 | N23: M | O23: N | P23: Staff | Q23: 18000 | R23: 13371 | S23: 10800 | T23: 5400 | U23: 720 | V23: 540 | W23: 0 | X23: 0 | Y23: 540 | Z23: 540 | AA23: 0 | AB23: 0 | AC23: 0 | AD23: 0 | AE23: 4629 | AF23: 0 | AG23: 0 | AH23: 0 | AI23: 10 | AJ23: ='Row data'!$S23+'Row data'!$T23+'Row data'!$U23+'Row data'!$W23+'Row data'!$X23+'Row data'!$Y23+'Row data'!$Z23+'Row data'!$AA23+'Row data'!$AB23+'Row data'!$AD23-'Row data'!$AC23-'Row data'!$AE23-'Row data'!$AF23-'Row data'!$AG23-'Row data'!$AH23-'Row data'!$AI23 -> 13361 | AK23: 0 | AL23: 13361
A24: 23 | B24: ABC Textile Ltd. | C24: 6841704 | D24: Halim | E24: Admin | F24: Vehicle Management | G24: Driver | H24: 703204000030835 | I24: 44121 | L24: 32660 | M24: =IF('Row data'!$J24="",DATEDIF('Row data'!$L24,TODAY(),"y"),"0") -> 37 | N24: M | O24: N | P24: Staff | Q24: 21256 | R24: 20301 | S24: 12753 | T24: 6377 | U24: 850 | V24: 638 | W24: 0 | X24: 0 | Y24: 638 | Z24: 638 | AA24: 0 | AB24: 0 | AC24: -500 | AD24: 0 | AE24: 0 | AF24: 455 | AG24: 0 | AH24: 0 | AI24: 0 | AJ24: ='Row data'!$S24+'Row data'!$T24+'Row data'!$U24+'Row data'!$W24+'Row data'!$X24+'Row data'!$Y24+'Row data'!$Z24+'Row data'!$AA24+'Row data'!$AB24+'Row data'!$AD24-'Row data'!$AC24-'Row data'!$AE24-'Row data'!$AF24-'Row data'!$AG24-'Row data'!$AH24-'Row data'!$AI24 -> 21301 | AK24: 20301 | AL24: 0
A25: 24 | B25: ABC Textile Ltd. | C25: 9572996 | D25: Hasan | E25: Admin | F25: Vehicle Management | G25: Driver | H25: 703204000030460 | I25: 44853 | L25: 32549 | M25: =IF('Row data'!$J25="",DATEDIF('Row data'!$L25,TODAY(),"y"),"0") -> 37 | N25: M | O25: N | P25: Staff | Q25: 22496 | R25: 22496 | S25: 13497 | T25: 6749 | U25: 900 | V25: 675 | W25: 0 | X25: 0 | Y25: 675 | Z25: 675 | AA25: 0 | AB25: 0 | AC25: 0 | AD25: 0 | AE25: 0 | AF25: 0 | AG25: 0 | AH25: 0 | AI25: 0 | AJ25: ='Row data'!$S25+'Row data'!$T25+'Row data'!$U25+'Row data'!$W25+'Row data'!$X25+'Row data'!$Y25+'Row data'!$Z25+'Row data'!$AA25+'Row data'!$AB25+'Row data'!$AD25-'Row data'!$AC25-'Row data'!$AE25-'Row data'!$AF25-'Row data'!$AG25-'Row data'!$AH25-'Row data'!$AI25 -> 22496 | AK25: 22496 | AL25: 0
A26: 25 | B26: ABC Textile Ltd. | C26: 9836296 | D26: Helal | E26: Admin | F26: Vehicle Management | G26: Assistant Forklift Driver | H26: 703204000031248 | I26: 44501 | L26: 27740 | M26: =IF('Row data'!$J26="",DATEDIF('Row data'!$L26,TODAY(),"y"),"0") -> 50 | N26: M | O26: N | P26: Staff | Q26: 21951 | R26: 21951 | S26: 13170 | T26: 6585 | U26: 878 | V26: 659 | W26: 0 | X26: 0 | Y26: 659 | Z26: 659 | AA26: 0 | AB26: 0 | AC26: 0 | AD26: 0 | AE26: 0 | AF26: 0 | AG26: 0 | AH26: 0 | AI26: 0 | AJ26: ='Row data'!$S26+'Row data'!$T26+'Row data'!$U26+'Row data'!$W26+'Row data'!$X26+'Row data'!$Y26+'Row data'!$Z26+'Row data'!$AA26+'Row data'!$AB26+'Row data'!$AD26-'Row data'!$AC26-'Row data'!$AE26-'Row data'!$AF26-'Row data'!$AG26-'Row data'!$AH26-'Row data'!$AI26 -> 21951 | AK26: 21951 | AL26: 0
A27: 26 | B27: ABC Textile Ltd. | C27: 5420911 | D27: Hossain | E27: Delivery | F27: Delivery | G27: Trainee Officer | H27: 703204000031237 | I27: 44807 | L27: 36916 | M27: =IF('Row data'!$J27="",DATEDIF('Row data'!$L27,TODAY(),"y"),"0") -> 25 | N27: M | O27: N | P27: Staff | Q27: 16351 | R27: 16351 | S27: 9810 | T27: 4905 | U27: 654 | V27: 491 | W27: 0 | X27: 0 | Y27: 491 | Z27: 491 | AA27: 0 | AB27: 0 | AC27: 0 | AD27: 0 | AE27: 0 | AF27: 0 | AG27: 0 | AH27: 0 | AI27: 0 | AJ27: ='Row data'!$S27+'Row data'!$T27+'Row data'!$U27+'Row data'!$W27+'Row data'!$X27+'Row data'!$Y27+'Row data'!$Z27+'Row data'!$AA27+'Row data'!$AB27+'Row data'!$AD27-'Row data'!$AC27-'Row data'!$AE27-'Row data'!$AF27-'Row data'!$AG27-'Row data'!$AH27-'Row data'!$AI27 -> 16351 | AK27: 16351 | AL27: 0
A28: 27 | B28: ABC Textile Ltd. | C28: 9713316 | D28: Iftekhar | E28: HR & Compliance | F28: Administration | G28: Asst. Admin Officer | H28: 9993204000003200 | I28: 44573 | L28: 31402 | M28: =IF('Row data'!$J28="",DATEDIF('Row data'!$L28,TODAY(),"y"),"0") -> 40 | N28: M | O28: N | P28: Staff | Q28: 22345 | R28: 22345 | S28: 13407 | T28: 6704 | U28: 894 | V28: 670 | W28: 0 | X28: 0 | Y28: 670 | Z28: 670 | AA28: 0 | AB28: 0 | AC28: 0 | AD28: 0 | AE28: 0 | AF28: 0 | AG28: 0 | AH28: 0 | AI28: 0 | AJ28: ='Row data'!$S28+'Row data'!$T28+'Row data'!$U28+'Row data'!$W28+'Row data'!$X28+'Row data'!$Y28+'Row data'!$Z28+'Row data'!$AA28+'Row data'!$AB28+'Row data'!$AD28-'Row data'!$AC28-'Row data'!$AE28-'Row data'!$AF28-'Row data'!$AG28-'Row data'!$AH28-'Row data'!$AI28 -> 22345 | AK28: 22345 | AL28: 0
A29: 28 | B29: ABC Textile Ltd. | C29: 7034621 | D29: Imran | E29: HR & Compliance | F29: HR | G29: Executive | H29: 9993204000003160 | I29: 43678 | L29: 32752 | M29: =IF('Row data'!$J29="",DATEDIF('Row data'!$L29,TODAY(),"y"),"0") -> 37 | N29: M | O29: N | P29: Staff | Q29: 27251 | R29: 27251 | S29: 16350 | T29: 8175 | U29: 1090 | V29: 818 | W29: 0 | X29: 0 | Y29: 818 | Z29: 818 | AA29: 0 | AB29: 0 | AC29: 0 | AD29: 0 | AE29: 0 | AF29: 0 | AG29: 2500 | AH29: 0 | AI29: 0 | AJ29: ='Row data'!$S29+'Row data'!$T29+'Row data'!$U29+'Row data'!$W29+'Row data'!$X29+'Row data'!$Y29+'Row data'!$Z29+'Row data'!$AA29+'Row data'!$AB29+'Row data'!$AD29-'Row data'!$AC29-'Row data'!$AE29-'Row data'!$AF29-'Row data'!$AG29-'Row data'!$AH29-'Row data'!$AI29 -> 24751 | AK29: 24751 | AL29: 0
A30: 29 | B30: ABC Textile Ltd. | C30: 8555326 | D30: Iqbal | E30: IT | F30: Information Technology | G30: Executive | H30: 9993201000341460 | I30: 44480 | L30: 35431 | M30: =IF('Row data'!$J30="",DATEDIF('Row data'!$L30,TODAY(),"y"),"0") -> 29 | N30: M | O30: N | P30: Staff | Q30: 32700 | R30: 32700 | S30: 19620 | T30: 9810 | U30: 1308 | V30: 981 | W30: 0 | X30: 0 | Y30: 981 | Z30: 981 | AA30: 0 | AB30: 0 | AC30: 0 | AD30: 0 | AE30: 0 | AF30: 0 | AG30: 0 | AH30: 0 | AI30: 0 | AJ30: ='Row data'!$S30+'Row data'!$T30+'Row data'!$U30+'Row data'!$W30+'Row data'!$X30+'Row data'!$Y30+'Row data'!$Z30+'Row data'!$AA30+'Row data'!$AB30+'Row data'!$AD30-'Row data'!$AC30-'Row data'!$AE30-'Row data'!$AF30-'Row data'!$AG30-'Row data'!$AH30-'Row data'!$AI30 -> 32700 | AK30: 32700 | AL30: 0
A31: 30 | B31: ABC Textile Ltd. | C31: 7352540 | D31: Ishtiaq | E31: Production | F31: Andritz Geo | G31: Shift Engineer | H31: 7863241000026650 | I31: 44604 | L31: 33313 | M31: =IF('Row data'!$J31="",DATEDIF('Row data'!$L31,TODAY(),"y"),"0") -> 35 | N31: M | O31: N | P31: Staff | Q31: 34879 | R31: 34879 | S31: 20928 | T31: 10464 | U31: 1395 | V31: 1046 | W31: 0 | X31: 0 | Y31: 1046 | Z31: 1046 | AA31: 0 | AB31: 0 | AC31: 0 | AD31: 0 | AE31: 0 | AF31: 0 | AG31: 0 | AH31: 0 | AI31: 0 | AJ31: ='Row data'!$S31+'Row data'!$T31+'Row data'!$U31+'Row data'!$W31+'Row data'!$X31+'Row data'!$Y31+'Row data'!$Z31+'Row data'!$AA31+'Row data'!$AB31+'Row data'!$AD31-'Row data'!$AC31-'Row data'!$AE31-'Row data'!$AF31-'Row data'!$AG31-'Row data'!$AH31-'Row data'!$AI31 -> 34879 | AK31: 34879 | AL31: 0
A32: 31 | B32: ABC Textile Ltd. | C32: 6659696 | D32: Jakir | E32: Production | F32: Andritz Geo | G32: Shift Engineer | H32: 9993204000003310 | I32: 45241 | L32: 36932 | M32: =IF('Row data'!$J32="",DATEDIF('Row data'!$L32,TODAY(),"y"),"0") -> 25 | N32: M | O32: N | P32: Staff | Q32: 21256 | R32: 21256 | S32: 12753 | T32: 6377 | U32: 850 | V32: 638 | W32: 0 | X32: 0 | Y32: 638 | Z32: 638 | AA32: 0 | AB32: 0 | AC32: 0 | AD32: 0 | AE32: 0 | AF32: 0 | AG32: 0 | AH32: 0 | AI32: 0 | AJ32: ='Row data'!$S32+'Row data'!$T32+'Row data'!$U32+'Row data'!$W32+'Row data'!$X32+'Row data'!$Y32+'Row data'!$Z32+'Row data'!$AA32+'Row data'!$AB32+'Row data'!$AD32-'Row data'!$AC32-'Row data'!$AE32-'Row data'!$AF32-'Row data'!$AG32-'Row data'!$AH32-'Row data'!$AI32 -> 21256 | AK32: 21256 | AL32: 0
A33: 32 | B33: ABC Textile Ltd. | C33: 8252375 | D33: Jalal | E33: Production | F33: Andritz Geo | G33: Trainee Shift Engineer | H33: 9993201000466550 | I33: 43785 | L33: 36393 | M33: =IF('Row data'!$J33="",DATEDIF('Row data'!$L33,TODAY(),"y"),"0") -> 27 | N33: M | O33: N | P33: Staff | Q33: 27251 | R33: 27251 | S33: 16350 | T33: 8175 | U33: 1090 | V33: 818 | W33: 0 | X33: 0 | Y33: 818 | Z33: 818 | AA33: 0 | AB33: 0 | AC33: 0 | AD33: 0 | AE33: 0 | AF33: 0 | AG33: 0 | AH33: 0 | AI33: 0 | AJ33: ='Row data'!$S33+'Row data'!$T33+'Row data'!$U33+'Row data'!$W33+'Row data'!$X33+'Row data'!$Y33+'Row data'!$Z33+'Row data'!$AA33+'Row data'!$AB33+'Row data'!$AD33-'Row data'!$AC33-'Row data'!$AE33-'Row data'!$AF33-'Row data'!$AG33-'Row data'!$AH33-'Row data'!$AI33 -> 27251 | AK33: 27251 | AL33: 0
A34: 33 | B34: ABC Textile Ltd. | C34: 7953821 | D34: Jahangir | E34: Production | F34: Andritz Geo | G34: Shift Engineer | H34: 9993201000306610 | I34: 44216 | L34: 34428 | M34: =IF('Row data'!$J34="",DATEDIF('Row data'!$L34,TODAY(),"y"),"0") -> 32 | N34: M | O34: N | P34: Staff | Q34: 26787 | R34: 21787 | S34: 16072 | T34: 8036 | U34: 1071 | V34: 804 | W34: 0 | X34: 0 | Y34: 804 | Z34: 804 | AA34: 0 | AB34: 0 | AC34: -5000 | AD34: 0 | AE34: 0 | AF34: 0 | AG34: 0 | AH34: 0 | AI34: 0 | AJ34: ='Row data'!$S34+'Row data'!$T34+'Row data'!$U34+'Row data'!$W34+'Row data'!$X34+'Row data'!$Y34+'Row data'!$Z34+'Row data'!$AA34+'Row data'!$AB34+'Row data'!$AD34-'Row data'!$AC34-'Row data'!$AE34-'Row data'!$AF34-'Row data'!$AG34-'Row data'!$AH34-'Row data'!$AI34 -> 31787 | AK34: 21787 | AL34: 0
A35: 34 | B35: ABC Textile Ltd. | C35: 8949990 | D35: Jahid | E35: Production | F35: Andritz Geo | G35: Sr. Shift Engineer | H35: 9993201000061280 | I35: 43040 | L35: 32969 | M35: =IF('Row data'!$J35="",DATEDIF('Row data'!$L35,TODAY(),"y"),"0") -> 36 | N35: M | O35: N | P35: Staff | Q35: 36461 | R35: 36461 | S35: 21877 | T35: 10938 | U35: 1458 | V35: 1094 | W35: 0 | X35: 0 | Y35: 1094 | Z35: 1094 | AA35: 0 | AB35: 0 | AC35: 0 | AD35: 0 | AE35: 0 | AF35: 0 | AG35: 0 | AH35: 0 | AI35: 0 | AJ35: ='Row data'!$S35+'Row data'!$T35+'Row data'!$U35+'Row data'!$W35+'Row data'!$X35+'Row data'!$Y35+'Row data'!$Z35+'Row data'!$AA35+'Row data'!$AB35+'Row data'!$AD35-'Row data'!$AC35-'Row data'!$AE35-'Row data'!$AF35-'Row data'!$AG35-'Row data'!$AH35-'Row data'!$AI35 -> 36461 | AK35: 36461 | AL35: 0
... A42: 41 | B42: ABC Textile Ltd. | C42: 6776594 | D42: Mahbub | E42: Production | F42: Needle Punch | G42: Supervisor | H42: 9993201000321990 | I42: 44352 | L42: 32051 | M42: =IF('Row data'!$J42="",DATEDIF('Row data'!$L42,TODAY(),"y"),"0") -> 38 | N42: M | O42: N | P42: Staff | Q42: 40875 | R42: 40875 | S42: 24525 | T42: 12263 | U42: 1635 | V42: 1226 | W42: 0 | X42: 0 | Y42: 1226 | Z42: 1226 | AA42: 0 | AB42: 0 | AC42: 0 | AD42: 0 | AE42: 0 | AF42: 0 | AG42: 0 | AH42: 0 | AI42: 0 | AJ42: ='Row data'!$S42+'Row data'!$T42+'Row data'!$U42+'Row data'!$W42+'Row data'!$X42+'Row data'!$Y42+'Row data'!$Z42+'Row data'!$AA42+'Row data'!$AB42+'Row data'!$AD42-'Row data'!$AC42-'Row data'!$AE42-'Row data'!$AF42-'Row data'!$AG42-'Row data'!$AH42-'Row data'!$AI42 -> 40875 | AK42: 40875 | AL42: 0
A43: 42 | B43: ABC Textile Ltd. | C43: 8801301 | D43: Mahdi | E43: Production | F43: Sewing Geo | G43: Assistant Operator | H43: 9993204000006530 | I43: 42409 | J43: 44572 | K43: =YEAR('Row data'!$J43) -> 2022 | L43: 34895 | M43: =IF('Row data'!$J43="",DATEDIF('Row data'!$L43,TODAY(),"y"),"0") -> 0 | N43: M | O43: N | P43: Staff | Q43: 16097 | R43: 16097 | S43: 9658 | T43: 4829 | U43: 644 | V43: 483 | W43: 0 | X43: 0 | Y43: 483 | Z43: 483 | AA43: 0 | AB43: 0 | AC43: 0 | AD43: 0 | AE43: 0 | AF43: 0 | AG43: 0 | AH43: 0 | AI43: 0 | AJ43: ='Row data'!$S43+'Row data'!$T43+'Row data'!$U43+'Row data'!$W43+'Row data'!$X43+'Row data'!$Y43+'Row data'!$Z43+'Row data'!$AA43+'Row data'!$AB43+'Row data'!$AD43-'Row data'!$AC43-'Row data'!$AE43-'Row data'!$AF43-'Row data'!$AG43-'Row data'!$AH43-'Row data'!$AI43 -> 16097 | AK43: 16097 | AL43: 0
A44: 43 | B44: ABC Textile Ltd. | C44: 9717095 | D44: Mahfuz | E44: Production | F44: Sewing Geo | G44: Quality Inspector | H44: 703204000030493 | I44: 43179 | L44: 35648 | M44: =IF('Row data'!$J44="",DATEDIF('Row data'!$L44,TODAY(),"y"),"0") -> 29 | N44: M | O44: N | P44: Staff | Q44: 16532 | R44: 16178 | S44: 9919 | T44: 4960 | U44: 661 | V44: 496 | W44: 0 | X44: 0 | Y44: 496 | Z44: 496 | AA44: 0 | AB44: 0 | AC44: 0 | AD44: 0 | AE44: 354 | AF44: 0 | AG44: 0 | AH44: 0 | AI44: 0 | AJ44: ='Row data'!$S44+'Row data'!$T44+'Row data'!$U44+'Row data'!$W44+'Row data'!$X44+'Row data'!$Y44+'Row data'!$Z44+'Row data'!$AA44+'Row data'!$AB44+'Row data'!$AD44-'Row data'!$AC44-'Row data'!$AE44-'Row data'!$AF44-'Row data'!$AG44-'Row data'!$AH44-'Row data'!$AI44 -> 16178 | AK44: 16178 | AL44: 0
A45: 44 | B45: ABC Textile Ltd. | C45: 7773498 | D45: Mamun | E45: Production | F45: Sewing Geo | G45: Assistant Supervisor | H45: 703204000030518 | I45: 42448 | L45: 34745 | M45: =IF('Row data'!$J45="",DATEDIF('Row data'!$L45,TODAY(),"y"),"0") -> 31 | N45: M | O45: N | P45: Staff | Q45: 22891 | R45: 22891 | S45: 13734 | T45: 6867 | U45: 916 | V45: 687 | W45: 0 | X45: 0 | Y45: 687 | Z45: 687 | AA45: 0 | AB45: 0 | AC45: 0 | AD45: 0 | AE45: 0 | AF45: 0 | AG45: 0 | AH45: 0 | AI45: 0 | AJ45: ='Row data'!$S45+'Row data'!$T45+'Row data'!$U45+'Row data'!$W45+'Row data'!$X45+'Row data'!$Y45+'Row data'!$Z45+'Row data'!$AA45+'Row data'!$AB45+'Row data'!$AD45-'Row data'!$AC45-'Row data'!$AE45-'Row data'!$AF45-'Row data'!$AG45-'Row data'!$AH45-'Row data'!$AI45 -> 22891 | AK45: 22891 | AL45: 0
A46: 45 | B46: ABC Textile Ltd. | C46: 6974260 | D46: Maruf | E46: Production | F46: Sewing Geo | G46: Quality Inspector | H46: 703204000030970 | I46: 43138 | L46: 36239 | M46: =IF('Row data'!$J46="",DATEDIF('Row data'!$L46,TODAY(),"y"),"0") -> 27 | N46: M | O46: N | P46: Staff | Q46: 16532 | R46: 16532 | S46: 9919 | T46: 4960 | U46: 661 | V46: 496 | W46: 0 | X46: 0 | Y46: 496 | Z46: 496 | AA46: 0 | AB46: 0 | AC46: 0 | AD46: 0 | AE46: 0 | AF46: 0 | AG46: 0 | AH46: 0 | AI46: 0 | AJ46: ='Row data'!$S46+'Row data'!$T46+'Row data'!$U46+'Row data'!$W46+'Row data'!$X46+'Row data'!$Y46+'Row data'!$Z46+'Row data'!$AA46+'Row data'!$AB46+'Row data'!$AD46-'Row data'!$AC46-'Row data'!$AE46-'Row data'!$AF46-'Row data'!$AG46-'Row data'!$AH46-'Row data'!$AI46 -> 16532 | AK46: 16532 | AL46: 0
...

Sheet Demo Ans
B2: 1. How many employees are currently working in the company?
B4: =SUM(COUNTA('Row data'!I2:I606)-SUM(COUNTA('Row data'!J2:J606)))& " People " -> 404 People
B6: 2. What is the gender distribution of employees?
B8: =COUNTIF('Row data'!N2:N606,"M")&" Male , " &COUNTIF('Row data'!N2:N606,"F")&" Fmale" -> 400 Male , 205 Fmale
B11: 3. What is the average age of employees Male and Female? | D11: Averageif
B13: Male | C13: =AVERAGEIF('Row data'!N2:N606,"M",'Row data'!M2:M606) -> 35.757937 | D13: Female | E13: =AVERAGEIF('Row data'!N2:N606,"F",'Row data'!M2:M606) -> 40.111842
B15: 4. How many employees joined this year?
B17: =COUNTIFS('Row data'!I2:I606,">=2025-01-01",'Row data'!I2:I606,"<=2025-12-31") -> 6
B19: 5. What is the attrition rate (employees who quit last 5 years)
B21: Year | C21: Total Quit | D21: Percentage
B22: 2025 | C22: 4 | D22: 0.019900498
B23: 2024 | C23: 10 | D23: 0.049751244
B24: 2023 | C24: 10 | D24: 0.049751244
B25: 2022 | C25: 135 | D25: 0.67164179
B26: 2021 | C26: 9 | D26: 0.044776119
B27: 2020 | C27: 7 | D27: 0.034825871
B28: 2019 | C28: 14 | D28: 0.069651741
B29: 2018 | C29: 12 | D29: 0.059701493
B33: Year | C33: Total Quit | D33: Percentage
B34: 2021 | C34: =COUNTIF('Row data'!$K$2:$K$606,B34) -> 9 | D34: =C34/COUNTIFS('Row data'!$I$2:$I$606,">=2021-01-01",'Row data'!$I$2:$I$606,"<=2021-12-31") -> 0.1125
B35: 2022 | C35: =COUNTIF('Row data'!$K$2:$K$606,B35) -> 135 | D35: =C35/COUNTIFS('Row data'!$I$2:$I$606,">=2022-01-01",'Row data'!$I$2:$I$606,"<=2022-12-31") -> 1.8243243
B36: 2023 | C36: =COUNTIF('Row data'!$K$2:$K$606,B36) -> 10 | D36: =C36/COUNTIFS('Row data'!$I$2:$I$606,">=2023-01-01",'Row data'!$I$2:$I$606,"<=2023-12-31") -> 0.12195122
B37: 2024 | C37: =COUNTIF('Row data'!$K$2:$K$606,B37) -> 10 | D37: =$C$37/COUNTIFS('Row data'!$I$2:$I$606,">=2024-01-01",'Row data'!$I$2:$I$606,"<=2024-12-31") -> 0.71428571
B38: 2025 | C38: =COUNTIF('Row data'!$K$2:$K$606,B38) -> 4 | D38: =C38/COUNTIFS('Row data'!$I$2:$I$606,">=2025-01-01",'Row data'!$I$2:$I$606,"<=2025-12-31") -> 0.66666667

Sheet Demo Ans 2
B2: 6. What is the distribution of employees by designation name? | G2: 7. What is the distribution of employees by department and designation? | L2: 8. What is the average Total in each department? | P2: 9. Which department has the highest turnover rate? (depend on the total quit employees)
G3: Department | P3: Department | Q3: Join | R3: Quit | S3: Percentage
B4: Designation | C4: Employee | D4: Distribution | G4: Production | L4: Department | M4: Avg. Gross | N4: Avg. Gross Pay | P4: {=_xlfn.UNIQUE(Row[DeptName])} -> Production | Q4: =COUNTIFS(Row[DeptName],P4,Row[JDate],">=1995-01-01",Row[JDate],"<=2025-12-31") -> 457 | R4: =COUNTIFS(Row[DeptName],P4,Row[QuitDate],">=1995-01-01",Row[QuitDate],"<=2025-12-31") -> 130 | S4: =R4/Q4 -> 0.28446389
B5: {=_xlfn.UNIQUE('Row data'!$G$2:$G$606)} -> Trainee Officer | C5: =COUNTIF('Row data'!$G$2:$G$606,'Demo Ans 2'!B7) -> 153 | D5: =C5/SUM($C$5:$C$125) -> 0.25289256 | G5: Designation | H5: Employee | I5: Distribution | L5: {=_xlfn.UNIQUE(Row[DeptName])} -> Production | M5: =AVERAGEIFS(Row[Gross],Row[DeptName],L5) -> 16202.812 | N5: =AVERAGEIFS(Row[Gross Pay],Row[DeptName],L5) -> 15991.978 | P5: Utility & Maintenance | Q5: =COUNTIFS(Row[DeptName],P5,Row[JDate],">=1995-01-01",Row[JDate],"<=2025-12-31") -> 39 | R5: =COUNTIFS(Row[DeptName],P5,Row[QuitDate],">=1995-01-01",Row[QuitDate],"<=2025-12-31") -> 12 | S5: =R5/Q5 -> 0.30769231
B6: Head Fitter | C6: =COUNTIF('Row data'!$G$2:$G$606,'Demo Ans 2'!B28) -> 67 | D6: =C6/SUM($C$5:$C$125) -> 0.1107438 | G6: {=_xlfn.UNIQUE(_xlfn._xlws.FILTER('Row data'!$G$2:$G$606,'Row data'!$E$2:$E$606='Demo Ans 2'!$G$4))} -> Trainee Officer | H6: =COUNTIFS(Row[DeptName],$G$4,Row[DesigName],G6) -> 1 | I6: =H6/COUNTA(Row[EmpId]) -> 0.0016528926 | L6: Utility & Maintenance | M6: =AVERAGEIFS(Row[Gross],Row[DeptName],L6) -> 25814.564 | N6: =AVERAGEIFS(Row[Gross Pay],Row[DeptName],L6) -> 24706.513 | P6: Admin | Q6: =COUNTIFS(Row[DeptName],P6,Row[JDate],">=1995-01-01",Row[JDate],"<=2025-12-31") -> 83 | R6: =COUNTIFS(Row[DeptName],P6,Row[QuitDate],">=1995-01-01",Row[QuitDate],"<=2025-12-31") -> 47 | S6: =R6/Q6 -> 0.56626506
B7: Assistant | C7: =COUNTIF('Row data'!$G$2:$G$606,'Demo Ans 2'!B29) -> 42 | D7: =C7/SUM($C$5:$C$125) -> 0.069421488 | G7: Head Fitter | H7: =COUNTIFS(Row[DeptName],$G$4,Row[DesigName],G7) -> 1 | I7: =H7/COUNTA(Row[EmpId]) -> 0.0016528926 | L7: Admin | M7: =AVERAGEIFS(Row[Gross],Row[DeptName],L7) -> 21231.843 | N7: =AVERAGEIFS(Row[Gross Pay],Row[DeptName],L7) -> 20595.157 | P7: Delivery | Q7: =COUNTIFS(Row[DeptName],P7,Row[JDate],">=1995-01-01",Row[JDate],"<=2025-12-31") -> 6 | R7: =COUNTIFS(Row[DeptName],P7,Row[QuitDate],">=1995-01-01",Row[QuitDate],"<=2025-12-31") -> 2 | S7: =R7/Q7 -> 0.33333333
B8: Senior Fitter | C8: =COUNTIF('Row data'!$G$2:$G$606,'Demo Ans 2'!B92) -> 34 | D8: =C8/SUM($C$5:$C$125) -> 0.056198347 | G8: Assistant | H8: =COUNTIFS(Row[DeptName],$G$4,Row[DesigName],G8) -> 148 | I8: =H8/COUNTA(Row[EmpId]) -> 0.2446281 | L8: Delivery | M8: =AVERAGEIFS(Row[Gross],Row[DeptName],L8) -> 33999.5 | N8: =AVERAGEIFS(Row[Gross Pay],Row[DeptName],L8) -> 33166.167 | P8: HR & Compliance | Q8: =COUNTIFS(Row[DeptName],P8,Row[JDate],">=1995-01-01",Row[JDate],"<=2025-12-31") -> 4 | R8: =COUNTIFS(Row[DeptName],P8,Row[QuitDate],">=1995-01-01",Row[QuitDate],"<=2025-12-31") -> 0 | S8: =R8/Q8 -> 0
B9: Shift Engineer | C9: =COUNTIF('Row data'!$G$2:$G$606,'Demo Ans 2'!B23) -> 14 | D9: =C9/SUM($C$5:$C$125) -> 0.023140496 | G9: Senior Fitter | H9: =COUNTIFS(Row[DeptName],$G$4,Row[DesigName],G9) -> 1 | I9: =H9/COUNTA(Row[EmpId]) -> 0.0016528926 | L9: HR & Compliance | M9: =AVERAGEIFS(Row[Gross],Row[DeptName],L9) -> 32836.5 | N9: =AVERAGEIFS(Row[Gross Pay],Row[DeptName],L9) -> 31586.5 | P9: IT | Q9: =COUNTIFS(Row[DeptName],P9,Row[JDate],">=1995-01-01",Row[JDate],"<=2025-12-31") -> 2 | R9: =COUNTIFS(Row[DeptName],P9,Row[QuitDate],">=1995-01-01",Row[QuitDate],"<=2025-12-31") -> 1 | S9: =R9/Q9 -> 0.5
B10: Senior Supervisor | C10: =COUNTIF('Row data'!$G$2:$G$606,'Demo Ans 2'!B49) -> 13 | D10: =C10/SUM($C$5:$C$125) -> 0.021487603 | G10: Shift Engineer | H10: =COUNTIFS(Row[DeptName],$G$4,Row[DesigName],G10) -> 5 | I10: =H10/COUNTA(Row[EmpId]) -> 0.0082644628 | L10: IT | M10: =AVERAGEIFS(Row[Gross],Row[DeptName],L10) -> 41420 | N10: =AVERAGEIFS(Row[Gross Pay],Row[DeptName],L10) -> 41420 | P10: Store | Q10: =COUNTIFS(Row[DeptName],P10,Row[JDate],">=1995-01-01",Row[JDate],"<=2025-12-31") -> 12 | R10: =COUNTIFS(Row[DeptName],P10,Row[QuitDate],">=1995-01-01",Row[QuitDate],"<=2025-12-31") -> 8 | S10: =R10/Q10 -> 0.66666667
B11: Junior Executive | C11: =COUNTIF('Row data'!$G$2:$G$606,'Demo Ans 2'!B27) -> 11 | D11: =C11/SUM($C$5:$C$125) -> 0.018181818 | G11: Senior Supervisor | H11: =COUNTIFS(Row[DeptName],$G$4,Row[DesigName],G11) -> 7 | I11: =H11/COUNTA(Row[EmpId]) -> 0.011570248 | L11: Store | M11: =AVERAGEIFS(Row[Gross],Row[DeptName],L11) -> 20718.417 | N11: =AVERAGEIFS(Row[Gross Pay],Row[DeptName],L11) -> 19604.583 | P11: Accounts | Q11: =COUNTIFS(Row[DeptName],P11,Row[JDate],">=1995-01-01",Row[JDate],"<=2025-12-31") -> 2 | R11: =COUNTIFS(Row[DeptName],P11,Row[QuitDate],">=1995-01-01",Row[QuitDate],"<=2025-12-31") -> 1 | S11: =R11/Q11 -> 0.5
B12: Assistant Cook | C12: =COUNTIF('Row data'!$G$2:$G$606,'Demo Ans 2'!B16) -> 10 | D12: =C12/SUM($C$5:$C$125) -> 0.016528926 | G12: Trainee Shift Engineer | H12: =COUNTIFS(Row[DeptName],$G$4,Row[DesigName],G12) -> 1 | I12: =H12/COUNTA(Row[EmpId]) -> 0.0016528926 | L12: Accounts | M12: =AVERAGEIFS(Row[Gross],Row[DeptName],L12) -> 47905.5 | N12: =AVERAGEIFS(Row[Gross Pay],Row[DeptName],L12) -> 47905.5
B13: Cook | C13: =COUNTIF('Row data'!$G$2:$G$606,'Demo Ans 2'!B17) -> 10 | D13: =C13/SUM($C$5:$C$125) -> 0.016528926 | G13: Sr. Shift Engineer | H13: =COUNTIFS(Row[DeptName],$G$4,Row[DesigName],G13) -> 1 | I13: =H13/COUNTA(Row[EmpId]) -> 0.0016528926
B14: Deputy General Manager | C14: =COUNTIF('Row data'!$G$2:$G$606,'Demo Ans 2'!B66) -> 9 | D14: =C14/SUM($C$5:$C$125) -> 0.014876033 | G14: Assistant Bundleman | H14: =COUNTIFS(Row[DeptName],$G$4,Row[DesigName],G14) -> 14 | I14: =H14/COUNTA(Row[EmpId]) -> 0.023140496
B15: Lady Checker | C15: =COUNTIF('Row data'!$G$2:$G$606,'Demo Ans 2'!B78) -> 9 | D15: =C15/SUM($C$5:$C$125) -> 0.014876033 | G15: Designer | H15: =COUNTIFS(Row[DeptName],$G$4,Row[DesigName],G15) -> 1 | I15: =H15/COUNTA(Row[EmpId]) -> 0.0016528926
B16: Loader | C16: =COUNTIF('Row data'!$G$2:$G$606,'Demo Ans 2'!B83) -> 8 | D16: =C16/SUM($C$5:$C$125) -> 0.01322314 | G16: Supervisor | H16: =COUNTIFS(Row[DeptName],$G$4,Row[DesigName],G16) -> 5 | I16: =H16/COUNTA(Row[EmpId]) -> 0.0082644628
B17: Driver | C17: =COUNTIF('Row data'!$G$2:$G$606,'Demo Ans 2'!B93) -> 8 | D17: =C17/SUM($C$5:$C$125) -> 0.01322314 | G17: Laser Cutting Machine Operator | H17: =COUNTIFS(Row[DeptName],$G$4,Row[DesigName],G17) -> 1 | I17: =H17/COUNTA(Row[EmpId]) -> 0.0016528926
B18: Assistant Forklift Driver | C18: =COUNTIF('Row data'!$G$2:$G$606,'Demo Ans 2'!B10) -> 7 | D18: =C18/SUM($C$5:$C$125) -> 0.011570248 | G18: Quality Inspector | H18: =COUNTIFS(Row[DeptName],$G$4,Row[DesigName],G18) -> 11 | I18: =H18/COUNTA(Row[EmpId]) -> 0.018181818
B19: Asst. Admin Officer | C19: =COUNTIF('Row data'!$G$2:$G$606,'Demo Ans 2'!B69) -> 7 | D19: =C19/SUM($C$5:$C$125) -> 0.011570248 | G19: Operator | H19: =COUNTIFS(Row[DeptName],$G$4,Row[DesigName],G19) -> 66 | I19: =H19/COUNTA(Row[EmpId]) -> 0.10909091
B20: Executive | C20: =COUNTIF('Row data'!$G$2:$G$606,'Demo Ans 2'!B85) -> 7 | D20: =C20/SUM($C$5:$C$125) -> 0.011570248 | G20: Assistant Operator | H20: =COUNTIFS(Row[DeptName],$G$4,Row[DesigName],G20) -> 42 | I20: =H20/COUNTA(Row[EmpId]) -> 0.069421488
B21: Trainee Shift Engineer | C21: =COUNTIF('Row data'!$G$2:$G$606,'Demo Ans 2'!B97) -> 7 | D21: =C21/SUM($C$5:$C$125) -> 0.011570248 | G21: Assistant Supervisor | H21: =COUNTIFS(Row[DeptName],$G$4,Row[DesigName],G21) -> 2 | I21: =H21/COUNTA(Row[EmpId]) -> 0.0033057851
B22: Sr. Shift Engineer | C22: =COUNTIF('Row data'!$G$2:$G$606,'Demo Ans 2'!B9) -> 6 | D22: =C22/SUM($C$5:$C$125) -> 0.0099173554 | G22: Mechanic | H22: =COUNTIFS(Row[DeptName],$G$4,Row[DesigName],G22) -> 2 | I22: =H22/COUNTA(Row[EmpId]) -> 0.0033057851
B23: Assistant Bundleman | C23: =COUNTIF('Row data'!$G$2:$G$606,'Demo Ans 2'!B32) -> 6 | D23: =C23/SUM($C$5:$C$125) -> 0.0099173554 | G23: General Quality Inspector | H23: =COUNTIFS(Row[DeptName],$G$4,Row[DesigName],G23) -> 6 | I23: =H23/COUNTA(Row[EmpId]) -> 0.0099173554
B24: Designer | C24: =COUNTIF('Row data'!$G$2:$G$606,'Demo Ans 2'!B25) -> 5 | D24: =C24/SUM($C$5:$C$125) -> 0.0082644628 | G24: Senior Packingman | H24: =COUNTIFS(Row[DeptName],$G$4,Row[DesigName],G24) -> 1 | I24: =H24/COUNTA(Row[EmpId]) -> 0.0016528926
B25: Supervisor | C25: =COUNTIF('Row data'!$G$2:$G$606,'Demo Ans 2'!B64) -> 5 | D25: =C25/SUM($C$5:$C$125) -> 0.0082644628 | G25: Senior Operator | H25: =COUNTIFS(Row[DeptName],$G$4,Row[DesigName],G25) -> 2 | I25: =H25/COUNTA(Row[EmpId]) -> 0.0033057851
B26: Laser Cutting Machine Operator | C26: =COUNTIF('Row data'!$G$2:$G$606,'Demo Ans 2'!B86) -> 5 | D26: =C26/SUM($C$5:$C$125) -> 0.0082644628 | G26: Padding Machine Operator | H26: =COUNTIFS(Row[DeptName],$G$4,Row[DesigName],G26) -> 3 | I26: =H26/COUNTA(Row[EmpId]) -> 0.0049586777
B27: Quality Inspector | C27: =COUNTIF('Row data'!$G$2:$G$606,'Demo Ans 2'!B5) -> 4 | D27: =C27/SUM($C$5:$C$125) -> 0.0066115702 | G27: Senior Carding Operator | H27: =COUNTIFS(Row[DeptName],$G$4,Row[DesigName],G27) -> 1 | I27: =H27/COUNTA(Row[EmpId]) -> 0.0016528926
B28: Operator | C28: =COUNTIF('Row data'!$G$2:$G$606,'Demo Ans 2'!B12) -> 4 | D28: =C28/SUM($C$5:$C$125) -> 0.0066115702 | G28: Asst. Production Incharge | H28: =COUNTIFS(Row[DeptName],$G$4,Row[DesigName],G28) -> 1 | I28: =H28/COUNTA(Row[EmpId]) -> 0.0016528926
B29: Assistant Operator | C29: =COUNTIF('Row data'!$G$2:$G$606,'Demo Ans 2'!B35) -> 4 | D29: =C29/SUM($C$5:$C$125) -> 0.0066115702 | G29: In Charge | H29: =COUNTIFS(Row[DeptName],$G$4,Row[DesigName],G29) -> 2 | I29: =H29/COUNTA(Row[EmpId]) -> 0.0033057851
B30: Assistant Supervisor | C30: =COUNTIF('Row data'!$G$2:$G$606,'Demo Ans 2'!B36) -> 4 | D30: =C30/SUM($C$5:$C$125) -> 0.0066115702 | G30: Deputy Production Incharge | H30: =COUNTIFS(Row[DeptName],$G$4,Row[DesigName],G30) -> 1 | I30: =H30/COUNTA(Row[EmpId]) -> 0.0016528926
B31: Mechanic | C31: =COUNTIF('Row data'!$G$2:$G$606,'Demo Ans 2'!B90) -> 4 | D31: =C31/SUM($C$5:$C$125) -> 0.0066115702 | G31: Senior Quality Inspector | H31: =COUNTIFS(Row[DeptName],$G$4,Row[DesigName],G31) -> 2 | I31: =H31/COUNTA(Row[EmpId]) -> 0.0033057851
B32: General Quality Inspector | C32: =COUNTIF('Row data'!$G$2:$G$606,'Demo Ans 2'!B107) -> 4 | D32: =C32/SUM($C$5:$C$125) -> 0.0066115702 | G32: Asst. Production Coordinator | H32: =COUNTIFS(Row[DeptName],$G$4,Row[DesigName],G32) -> 1 | I32: =H32/COUNTA(Row[EmpId]) -> 0.0016528926
B33: Store Co-Ordinator(Assistant) | C33: =COUNTIF('Row data'!$G$2:$G$606,'Demo Ans 2'!B123) -> 4 | D33: =C33/SUM($C$5:$C$125) -> 0.0066115702 | G33: Senior Padding Machine Operator | H33: =COUNTIFS(Row[DeptName],$G$4,Row[DesigName],G33) -> 1 | I33: =H33/COUNTA(Row[EmpId]) -> 0.0016528926
B34: Store Officer | C34: =COUNTIF('Row data'!$G$2:$G$606,'Demo Ans 2'!B22) -> 3 | D34: =C34/SUM($C$5:$C$125) -> 0.0049586777 | G34: Winder Machine Operator | H34: =COUNTIFS(Row[DeptName],$G$4,Row[DesigName],G34) -> 2 | I34: =H34/COUNTA(Row[EmpId]) -> 0.0033057851
B35: Junior Executive (Electrical) | C35: =COUNTIF('Row data'!$G$2:$G$606,'Demo Ans 2'!B33) -> 3 | D35: =C35/SUM($C$5:$C$125) -> 0.0049586777 | G35: Mechanic Helper | H35: =COUNTIFS(Row[DeptName],$G$4,Row[DesigName],G35) -> 1 | I35: =H35/COUNTA(Row[EmpId]) -> 0.0016528926
B36: Assistant Electrician | C36: =COUNTIF('Row data'!$G$2:$G$606,'Demo Ans 2'!B40) -> 3 | D36: =C36/SUM($C$5:$C$125) -> 0.0049586777 | G36: Executive Procurement | H36: =COUNTIFS(Row[DeptName],$G$4,Row[DesigName],G36) -> 1 | I36: =H36/COUNTA(Row[EmpId]) -> 0.0016528926
B37: Electrician | C37: =COUNTIF('Row data'!$G$2:$G$606,'Demo Ans 2'!B42) -> 3 | D37: =C37/SUM($C$5:$C$125) -> 0.0049586777 | G37: Asst. Supervisor | H37: =COUNTIFS(Row[DeptName],$G$4,Row[DesigName],G37) -> 1 | I37: =H37/COUNTA(Row[EmpId]) -> 0.0016528926
B38: Maintenance Officer | C38: =COUNTIF('Row data'!$G$2:$G$606,'Demo Ans 2'!B43) -> 3 | D38: =C38/SUM($C$5:$C$125) -> 0.0049586777 | G38: Assistant Bale Breaker Machine Operator | H38: =COUNTIFS(Row[DeptName],$G$4,Row[DesigName],G38) -> 7 | I38: =H38/COUNTA(Row[EmpId]) -> 0.011570248
B39: Asst. Manager | C39: =COUNTIF('Row data'!$G$2:$G$606,'Demo Ans 2'!B56) -> 3 | D39: =C39/SUM($C$5:$C$125) -> 0.0049586777 | G39: Cleaner | H39: =COUNTIFS(Row[DeptName],$G$4,Row[DesigName],G39) -> 3 | I39: =H39/COUNTA(Row[EmpId]) -> 0.0049586777
B40: Assistant Fitter Man | C40: =COUNTIF('Row data'!$G$2:$G$606,'Demo Ans 2'!B101) -> 3 | D40: =C40/SUM($C$5:$C$125) -> 0.0049586777 | G40: Assistant Winder Machine Operator | H40: =COUNTIFS(Row[DeptName],$G$4,Row[DesigName],G40) -> 5 | I40: =H40/COUNTA(Row[EmpId]) -> 0.0082644628
B41: Mechanical Fitter Man | C41: =COUNTIF('Row data'!$G$2:$G$606,'Demo Ans 2'!B104) -> 3 | D41: =C41/SUM($C$5:$C$125) -> 0.0049586777 | G41: General Winder Machine Operator | H41: =COUNTIFS(Row[DeptName],$G$4,Row[DesigName],G41) -> 1 | I41: =H41/COUNTA(Row[EmpId]) -> 0.0016528926
...

Sheet Demo Ans 3
G1: 11. Identify Employees with Highest Net Pay (Top 3) | N1: 12 Total Overtime Pay by Department | S1: 13 Employees with High Overtime but Low Salary | Z1: 14 Employee Loan vs. Net Pay Analysis
B2: 10. Average Salary by Department (Dynamic Lookup)
G3: EMP Name | H3: Department | I3: Salary | N3: Department | O3: OT | P3: OT Pay | S3: Overtime High and low salary
B4: Department | C4: Average salary (Gross) | G4: =_xlfn.XLOOKUP(I4,Row[Gross],Row[Employee Name],"Not Found",0) -> Rubel | H4: =LOOKUP(G4,Row[DeptName]) -> Production | I4: {=LARGE(Row[Gross],{1;2;3})} -> 185000 | N4: {=_xlfn.UNIQUE(Row[DeptName])} -> Production | O4: =COUNTIFS(Row[DeptName],N4,Row[OT],"Y") -> 386 | P4: =SUMIFS(Row[OT Amount],Row[DeptName],N4) -> 29503 | S4: Employee Name | T4: Low Salery | U4: OT Amount | V4: Net Pay | Z4: Employee Name | AA4: Lone Amount | AB4: Net Payble | AC4: Percent
B5: {=_xlfn.UNIQUE(Row[DeptName])} -> Production | C5: =AVERAGEIF(Row[DeptName],B5,Row[Gross]) -> 16202.812 | G5: =_xlfn.XLOOKUP(I5,Row[Gross],Row[Employee Name],"Not Found",0) -> Bashir | H5: =LOOKUP(G5,Row[DeptName]) -> Admin | I5: 135000 | N5: Utility & Maintenance | O5: =COUNTIFS(Row[DeptName],N5,Row[OT],"Y") -> 1 | P5: =SUMIFS(Row[OT Amount],Row[DeptName],N5) -> 0 | S5: {=_xlfn.SORTBY(_xlfn._xlws.FILTER(_xlfn.HSTACK(Row[Employee Name],Row[Gross],Row[OT Amount],Row[Net Payable]),Row[OT Amount]>0,""),_xlfn._xlws.FILTER(Row[OT Amount],Row[OT Amount]>0),1)} -> Abdul Aziz | T5: 13405 | U5: 4213 | V5: 17968 | Z5: {=_xlfn._xlws.FILTER(Row[Employee Name],Row[Loan]>0)} -> Aminul | AA5: =_xlfn.XLOOKUP(Z5,Row[Employee Name],Row[Loan],,0) -> 15000 | AB5: =_xlfn.XLOOKUP(Z5,Row[Employee Name],Row[Net Payable],,0) -> 17700 | AC5: =AA5/AB5 -> 0.84745763
B6: Utility & Maintenance | C6: =AVERAGEIF(Row[DeptName],B6,Row[Gross]) -> 25814.564 | G6: =_xlfn.XLOOKUP(I6,Row[Gross],Row[Employee Name],"Not Found",0) -> Siam | H6: =LOOKUP(G6,Row[DeptName]) -> Production | I6: 88727 | N6: Admin | O6: =COUNTIFS(Row[DeptName],N6,Row[OT],"Y") -> 11 | P6: =SUMIFS(Row[OT Amount],Row[DeptName],N6) -> 0 | S6: Grace | T6: 15337 | U6: 4626 | V6: 20313 | Z6: Imran | AA6: =_xlfn.XLOOKUP(Z6,Row[Employee Name],Row[Loan],,0) -> 2500 | AB6: =_xlfn.XLOOKUP(Z6,Row[Employee Name],Row[Net Payable],,0) -> 24751 | AC6: =AA6/AB6 -> 0.10100602
B7: Admin | C7: =AVERAGEIF(Row[DeptName],B7,Row[Gross]) -> 21231.843 | N7: Delivery | O7: =COUNTIFS(Row[DeptName],N7,Row[OT],"Y") -> 0 | P7: =SUMIFS(Row[OT Amount],Row[DeptName],N7) -> 0 | S7: George | T7: 13405 | U7: 4634 | V7: 18389 | Z7: Liton | AA7: =_xlfn.XLOOKUP(Z7,Row[Employee Name],Row[Loan],,0) -> 3000 | AB7: =_xlfn.XLOOKUP(Z7,Row[Employee Name],Row[Net Payable],,0) -> 23421 | AC7: =AA7/AB7 -> 0.12809018
B8: Delivery | C8: =AVERAGEIF(Row[DeptName],B8,Row[Gross]) -> 33999.5 | N8: HR & Compliance | O8: =COUNTIFS(Row[DeptName],N8,Row[OT],"Y") -> 0 | P8: =SUMIFS(Row[OT Amount],Row[DeptName],N8) -> 0 | S8: Grayson | T8: 13405 | U8: 4634 | V8: 18389 | Z8: Rashid | AA8: =_xlfn.XLOOKUP(Z8,Row[Employee Name],Row[Loan],,0) -> 5000 | AB8: =_xlfn.XLOOKUP(Z8,Row[Employee Name],Row[Net Payable],,0) -> 30533 | AC8: =AA8/AB8 -> 0.16375725
B9: HR & Compliance | C9: =AVERAGEIF(Row[DeptName],B9,Row[Gross]) -> 32836.5 | N9: IT | O9: =COUNTIFS(Row[DeptName],N9,Row[OT],"Y") -> 0 | P9: =SUMIFS(Row[OT Amount],Row[DeptName],N9) -> 0 | S9: Gabriel | T9: 14549 | U9: 4653 | V9: 19552 | Z9: Sagor | AA9: =_xlfn.XLOOKUP(Z9,Row[Employee Name],Row[Loan],,0) -> 500 | AB9: =_xlfn.XLOOKUP(Z9,Row[Employee Name],Row[Net Payable],,0) -> 23441 | AC9: =AA9/AB9 -> 0.021330148
B10: IT | C10: =AVERAGEIF(Row[DeptName],B10,Row[Gross]) -> 41420 | N10: Store | O10: =COUNTIFS(Row[DeptName],N10,Row[OT],"Y") -> 0 | P10: =SUMIFS(Row[OT Amount],Row[DeptName],N10) -> 0 | S10: Prosenjit Bappi | T10: 18388 | U10: 6743 | V10: 24481 | Z10: Shafayet | AA10: =_xlfn.XLOOKUP(Z10,Row[Employee Name],Row[Loan],,0) -> 4000 | AB10: =_xlfn.XLOOKUP(Z10,Row[Employee Name],Row[Net Payable],,0) -> 37515 | AC10: =AA10/AB10 -> 0.10662402
B11: Store | C11: =AVERAGEIF(Row[DeptName],B11,Row[Gross]) -> 20718.417 | N11: Accounts | O11: =COUNTIFS(Row[DeptName],N11,Row[OT],"Y") -> 0 | P11: =SUMIFS(Row[OT Amount],Row[DeptName],N11) -> 0 | Z11: Siam | AA11: =_xlfn.XLOOKUP(Z11,Row[Employee Name],Row[Loan],,0) -> 5000 | AB11: =_xlfn.XLOOKUP(Z11,Row[Employee Name],Row[Net Payable],,0) -> 81927 | AC11: =AA11/AB11 -> 0.061029941
B12: Accounts | C12: =AVERAGEIF(Row[DeptName],B12,Row[Gross]) -> 47905.5 | Z12: Sujan | AA12: =_xlfn.XLOOKUP(Z12,Row[Employee Name],Row[Loan],,0) -> 1500 | AB12: =_xlfn.XLOOKUP(Z12,Row[Employee Name],Row[Net Payable],,0) -> 14868 | AC12: =AA12/AB12 -> 0.10088781
Z13: Wahid | AA13: =_xlfn.XLOOKUP(Z13,Row[Employee Name],Row[Loan],,0) -> 3000 | AB13: =_xlfn.XLOOKUP(Z13,Row[Employee Name],Row[Net Payable],,0) -> 17136 | AC13: =AA13/AB13 -> 0.17507003
Z14: Alia | AA14: =_xlfn.XLOOKUP(Z14,Row[Employee Name],Row[Loan],,0) -> 3000 | AB14: =_xlfn.XLOOKUP(Z14,Row[Employee Name],Row[Net Payable],,0) -> 34942 | AC14: =AA14/AB14 -> 0.085856562
Z15: Anika | AA15: =_xlfn.XLOOKUP(Z15,Row[Employee Name],Row[Loan],,0) -> 2000 | AB15: =_xlfn.XLOOKUP(Z15,Row[Employee Name],Row[Net Payable],,0) -> 27457 | AC15: =AA15/AB15 -> 0.07284117
Z16: Labiba | AA16: =_xlfn.XLOOKUP(Z16,Row[Employee Name],Row[Loan],,0) -> 500 | AB16: =_xlfn.XLOOKUP(Z16,Row[Employee Name],Row[Net Payable],,0) -> 15063 | AC16: =AA16/AB16 -> 0.033193919
Z17: Maleka | AA17: =_xlfn.XLOOKUP(Z17,Row[Employee Name],Row[Loan],,0) -> 5000 | AB17: =_xlfn.XLOOKUP(Z17,Row[Employee Name],Row[Net Payable],,0) -> 20461 | AC17: =AA17/AB17 -> 0.24436733
Z18: Maria | AA18: =_xlfn.XLOOKUP(Z18,Row[Employee Name],Row[Loan],,0) -> 1000 | AB18: =_xlfn.XLOOKUP(Z18,Row[Employee Name],Row[Net Payable],,0) -> 26145 | AC18: =AA18/AB18 -> 0.038248231
Z19: Moushumi | AA19: =_xlfn.XLOOKUP(Z19,Row[Employee Name],Row[Loan],,0) -> 1000 | AB19: =_xlfn.XLOOKUP(Z19,Row[Employee Name],Row[Net Payable],,0) -> 14805 | AC19: =AA19/AB19 -> 0.067544748
Z20: Nasima | AA20: =_xlfn.XLOOKUP(Z20,Row[Employee Name],Row[Loan],,0) -> 5000 | AB20: =_xlfn.XLOOKUP(Z20,Row[Employee Name],Row[Net Payable],,0) -> 31078 | AC20: =AA20/AB20 -> 0.16088551
Z21: Nazia | AA21: =_xlfn.XLOOKUP(Z21,Row[Employee Name],Row[Loan],,0) -> 2000 | AB21: =_xlfn.XLOOKUP(Z21,Row[Employee Name],Row[Net Payable],,0) -> 19495 | AC21: =AA21/AB21 -> 0.10259041
Z22: Ritu | AA22: =_xlfn.XLOOKUP(Z22,Row[Employee Name],Row[Loan],,0) -> 500 | AB22: =_xlfn.XLOOKUP(Z22,Row[Employee Name],Row[Net Payable],,0) -> 15063 | AC22: =AA22/AB22 -> 0.033193919
Z23: Rumana | AA23: =_xlfn.XLOOKUP(Z23,Row[Employee Name],Row[Loan],,0) -> 3000 | AB23: =_xlfn.XLOOKUP(Z23,Row[Employee Name],Row[Net Payable],,0) -> 23705 | AC23: =AA23/AB23 -> 0.12655558
Z24: Tasfia | AA24: =_xlfn.XLOOKUP(Z24,Row[Employee Name],Row[Loan],,0) -> 1500 | AB24: =_xlfn.XLOOKUP(Z24,Row[Employee Name],Row[Net Payable],,0) -> 13837 | AC24: =AA24/AB24 -> 0.108405
... Z32: Kaitlyn | AA32: =_xlfn.XLOOKUP(Z32,Row[Employee Name],Row[Loan],,0) -> 500 | AB32: =_xlfn.XLOOKUP(Z32,Row[Employee Name],Row[Net Payable],,0) -> 13155 | AC32: =AA32/AB32 -> 0.038008362

Sheet Sheet2
B2: 1. How many employees are currently working in the company?
B4: 404 | D4: COUNT
B6: 2. What is the gender distribution of employees?
B8: 400 Male and 205 Female | D8: Countif
B11: 3. What is the average age of employees Male and Femaile? | D11: Averageif
B15: 4. How many employees joined each year?
B17: 6 | D17: Countifs
B19: 5. What is the attrition rate (employees who quit per year)?
B21: Year | C21: Total Emmployee | D21: Total Quit | E21: Percentage
B22: {=_xlfn.TAKE(_xlfn._xlws.SORT(_xlfn.UNIQUE(TEXT('Row data'!$I$2:$I$606,"YYYY")),1,-1),COUNTIF(_xlfn.ANCHORARRAY(D22),">0"))} -> 2025 | C22: {=COUNTIFS('Row data'!$K$2:$K$606,_xlfn.ANCHORARRAY(B22))} -> 4 | D22: {=COUNTIF('Row data'!$K$2:$K$606,_xlfn.ANCHORARRAY(B22))} -> 4 | E22: {=ROUND(_xlfn.ANCHORARRAY(D22)/SUM(_xlfn.ANCHORARRAY(D22)),2)} -> 0.02 | G22: Row Labels | H22: Count of Employee Name | I22: Count of QuitDate
B23: 2024 | C23: 10 | D23: 10 | E23: 0.05 | G23: 2025 | H23: 6 | I23: 4
B24: 2023 | C24: 10 | D24: 10 | E24: 0.05 | G24: 2024 | H24: 14 | I24: 12
B25: 2022 | C25: 135 | D25: 135 | E25: 0.67 | G25: 2023 | H25: 82 | I25: 43
B26: 2021 | C26: 9 | D26: 9 | E26: 0.04 | G26: 2022 | H26: 74 | I26: 9
B27: 2020 | C27: 7 | D27: 7 | E27: 0.03 | G27: 2021 | H27: 80 | I27: 17
B28: 2019 | C28: 14 | D28: 14 | E28: 0.07 | G28: 2020 | H28: 26 | I28: 6
B29: 2018 | C29: 12 | D29: 12 | E29: 0.06 | G29: 2019 | H29: 16 | I29: 2
G30: 2018 | H30: 45 | I30: 15
G31: 2017 | H31: 61 | I31: 21
G32: 2016 | H32: 28 | I32: 8
G33: 2015 | H33: 29 | I33: 10
G34: 2014 | H34: 20 | I34: 10
G35: 2013 | H35: 15 | I35: 5
G36: 2012 | H36: 15 | I36: 6
G37: 2011 | H37: 16 | I37: 2
G38: 2010 | H38: 17 | I38: 6
G39: 2009 | H39: 8 | I39: 5
G40: 2008 | H40: 8 | I40: 3
G41: 2007 | H41: 9 | I41: 1
... G43: 2005 | H43: 1 | I43: 1
G44: 2004 | H44: 1
G45: 2003 | H45: 10 | I45: 2
G46: 2002 | H46: 4 | I46: 2
G47: 2001 | H47: 6 | I47: 6
G48: 2000 | H48: 2
G49: 1999 | H49: 3 | I49: 2
G50: 1998 | H50: 3 | I50: 1
G51: 1997 | H51: 1
G52: 1996 | H52: 2 | I52: 1
G53: 1995 | H53: 2
...
